Workbook

Sheet MASTER
G1: 1 | H1: 2 | I1: 3 | J1: 4 | K1: 5 | L1: 6 | M1: 7 | N1: 8 | O1: 9 | P1: 10 | Q1: 11 | R1: 12 | S1: 13 | T1: 14 | U1: 15 | V1: 16 | W1: 17 | X1: 18 | Y1: 19 | Z1: 20 | AA1: 21 | AB1: 22 | AC1: 23 | AD1: 24 | AE1: 25 | AF1: 26 | AG1: 27 | AH1: 28 | AI1: 29 | AJ1: 30 | AK1: 31 | AL1: 32 | AM1: 33 | AN1: 34 | AO1: 35 | AP1: 36 | AQ1: 37 | AR1: 38 | AS1: 39 | AT1: 40 | AU1: 41 | AV1: 42 | AW1: 43 | AX1: 44 | AY1: 45 | AZ1: 46 | BA1: 47 | BB1: 48 | BC1: 49 | BD1: 50 | BE1: 51 | BF1: 52 | BG1: 53 | BH1: 54 | BI1: 55 | BJ1: 56 | BK1: 57 | BL1: 58 | BM1: 59 | BN1: 60 | BO1: 61 | BP1: 62 | BQ1: 63 | BR1: 64 | BS1: 65 | BT1: 66 | BU1: 67 | BV1: 68 | BW1: 69 | BX1: 70 | BY1: 71 | BZ1: 72 | CA1: 73 | CB1: 74 | CC1: 75 | CD1: 76 | CE1: 77 | CF1: 78
DA2: DIKETAHUI | DC2: DISETUJUI
DA10: TIGOR F. | DB10: OCTA YUDHA P. | DC10: EKO H./ANGGONO | DD10: M. RAJIEF A.P.
AH14: =200/15 -> 13.333333
AH15: =13*15 -> 195
G18: Hari Kerja | H18: 20
M21: Prod. Volume / month | P21: Prod. Volume | T21: Lot Size | Y21: Safety | AC21: Total | AD21: Ratio | AE21: PALLET | AK21: (meter) | AN21: (m2) | AQ21: (sec) | AR21: (minutes) / ITEM | AT21: (minutes) / MASTER | AZ21: CT Repair | BA21: TT/Part | BB21: PRESS LINE A | BF21: PRESS LINE B | BJ21: PRESS LINE C | BN21: PRESS LINE D | BU21: Total | BV21: Total | BW21: Item | BX21: Dies | CA21: Route
B22: SAME JOB | C22: PROSES LINE | E22: MACH | F22: NO | G22: JOB NO | H22: MASTER | I22: PART NO | J22: IRM NUMBER | K22: PART NAME | L22: Qty/Unit | M22: Regular | N22: Serv. Part | O22: TOTAL | P22: AVG/SHIFT | Q22: Avg/Shift (Master) | R22: Max/Shift | S22: Lot Cycle | T22: Each Part | U22: Master | V22: Lot/Shift | W22: Qty/Kbn | X22: Lot Size | Y22: Fluctuation | Z22: Down Time | AA22: Rep. Process | AB22: Total | AC22: Kanban | AD22: Kanban | AE22: Type Pallet | AF22: Type (Data IFP) | AG22: Qty | AH22: Total Need | AI22: Total Need (Mst) | AJ22: Act. Available | AK22: Panjang | AL22: Lebar | AM22: Toleransi | AN22: Std Tumpukan | AO22: Luas Area / Plt | AP22: Area FP | AQ22: CT | AR22: DCT | AS22: REG ACTIVITY | AT22: DCT | AU22: MCT | AV22: PCT | AW22: IP | AX22: DC | AY22: DT / Master | AZ22: (Sec.) | BA22: (Min) | BB22: A1 | BC22: A2 | BD22: A3 | BE22: A4 | BF22: B1 | BG22: B2 | BH22: B3 | BI22: B4 | BJ22: C1 | BK22: C2 | BL22: C3 | BM22: C4 | BN22: D1 | BO22: D2 | BP22: D3 | BQ22: D4 | BR22: Stroke/ Item | BS22: Total Process | BT22: Machine Process | BU22: Stroke/ Machine | BV22: Stroke/ Month/ Machine | BW22: Master/ Common | BX22: Mst/ Comm/ Gank | BY22: Sub Assy | BZ22: COSTUMER | CA22: CBU | CB22: CKD | CC22: Shut Height (mm) | CD22: Cushion Pressure (kg/cm2) | CE22: Remarks | CF22: TPT | CG22: PALLET AREA | CL22: Standard Safety 2~4 Hours | CM22: Lead Time (hours) | CN22: Takt Time Welding Assy Plant | CO22: Lead Time (Kanban) | CR22: SHUTHEIHGT
D23: variant | E23: A | G23: AAS-084 BLK | H23: AAS-084 BLK | I23: D57411 BZ280 | J23: IRM-093175 | K23: MBR FLOOR SIDE INNER RH | L23: 1 | M23: 3000 | O23: =+M23+N23 -> 3000 | P23: =+O23/$H$18 -> 150 | Q23: =IF($H23=G23,SUMIF($H:$H,H23,$P:$P),P23) -> 150 | R23: =Q23*10%+Q23 -> 165 | S23: 2 | T23: =IF(M23=0,"0",ROUNDUP(P23*S23/AG23,0)*AG23) -> 480 | U23: =IF($H23=G23,SUMIF($H:$H,H23,$T:$T),T23) -> 480 | V23: =IF(M23=0,"0",ROUND(P23/W23,1)) -> 2.5 | W23: 60 | X23: =ROUNDUP(T23/W23,0) -> 8 | AE23: KAYU | AG23: 240 | AQ23: 5.9 | AR23: 5 | BB23: 1 | BQ23: 1 | BR23: 1 | BS23: 1 | BU23: 1 | BV23: 6080 | BW23: M | BX23: M | BZ23: ADM | CF23: 40.416667
B24: AAS-084 | D24: variant | E24: A | G24: AAS-085 BLK | H24: AAS-085 BLK | I24: D57411 BZ280 | J24: IRM-093175 | K24: MBR FLOOR SIDE INNER RH | L24: 1 | M24: 3000 | O24: =+M24+N24 -> 3000 | P24: =+O24/$H$18 -> 150 | Q24: =IF($H24=G24,SUMIF($H:$H,H24,$P:$P),P24) -> 150 | R24: =Q24*10%+Q24 -> 165 | S24: 2 | T24: =IF(M24=0,"0",ROUNDUP(P24*S24/AG24,0)*AG24) -> 480 | U24: =IF($H24=G24,SUMIF($H:$H,H24,$T:$T),T24) -> 480 | V24: =IF(M24=0,"0",ROUND(P24/W24,1)) -> 2.5 | W24: 60 | X24: =ROUNDUP(T24/W24,0) -> 8 | AE24: KAYU | AG24: 240 | AQ24: 5.7 | AR24: 5 | BB24: 1 | BR24: 1 | BS24: 1 | BU24: 1 | BV24: 6080 | BW24: M | BX24: M | BZ24: ADM | CF24: 40.416667
B25: AAS-084 | D25: variant | E25: A | G25: AAS-084- | H25: AAS-009 | I25: D57411 BZ280 | J25: IRM-093175 | K25: MBR FLOOR SIDE INNER RH | L25: 1 | M25: 3000 | O25: =+M25+N25 -> 3000 | P25: =+O25/$H$18 -> 150 | Q25: =IF($H25=G25,SUMIF($H:$H,H25,$P:$P),P25) -> 150 | R25: =Q25*10%+Q25 -> 165 | S25: 2 | T25: =IF(M25=0,"0",ROUNDUP(P25*S25/AG25,0)*AG25) -> 300 | U25: =IF($H25=G25,SUMIF($H:$H,H25,$T:$T),T25) -> 300 | V25: =IF(M25=0,"0",ROUND(P25/W25,1)) -> 2.5 | W25: 60 | X25: =ROUNDUP(T25/W25,0) -> 5 | AE25: I | AG25: 60 | AQ25: 5.7 | AR25: 5 | BD25: 1 | BE25: 1 | BR25: 1 | BS25: 2 | BU25: 2 | BV25: 9960 | BW25: M | BX25: M | BZ25: ADM | CF25: 40.416667
B26: AAS-084 | D26: variant | E26: A | G26: AAS-084 | H26: AAS-009 | I26: D57411 BZ280 | J26: IRM-093175 | K26: MBR FLOOR SIDE INNER RH | L26: 1 | M26: 3000 | O26: =+M26+N26 -> 3000 | P26: =+O26/$H$18 -> 150 | Q26: =IF($H26=G26,SUMIF($H:$H,H26,$P:$P),P26) -> 150 | R26: =Q26*10%+Q26 -> 165 | S26: 2 | T26: =IF(M26=0,"0",ROUNDUP(P26*S26/AG26,0)*AG26) -> 300 | U26: =IF($H26=G26,SUMIF($H:$H,H26,$T:$T),T26) -> 300 | V26: =IF(M26=0,"0",ROUND(P26/W26,1)) -> 2.5 | W26: 60 | X26: =ROUNDUP(T26/W26,0) -> 5 | AE26: I | AG26: 60 | AQ26: 5.7 | AR26: 5 | BC26: 1 | BD26: 1 | BE26: 1 | BR26: 1 | BS26: 3 | BU26: 3 | BV26: 14940 | BW26: M | BX26: M | BZ26: ADM | CF26: 40.416667
B27: AAS-084 | D27: variant | E27: A | G27: AAS-085- | H27: AAS-010 | I27: D57412 BZ380 | J27: IRM-093175 | K27: MBR FLOOR SIDE INNER LH | L27: 1 | M27: 3000 | O27: =+M27+N27 -> 3000 | P27: =+O27/$H$18 -> 150 | Q27: =IF($H27=G27,SUMIF($H:$H,H27,$P:$P),P27) -> 150 | R27: =Q27*10%+Q27 -> 165 | S27: 2 | T27: =IF(M27=0,"0",ROUNDUP(P27*S27/AG27,0)*AG27) -> 300 | U27: =IF($H27=G27,SUMIF($H:$H,H27,$T:$T),T27) -> 300 | V27: =IF(M27=0,"0",ROUND(P27/W27,1)) -> 2.5 | W27: 60 | X27: =ROUNDUP(T27/W27,0) -> 5 | AE27: I | AG27: 60 | AQ27: 5.7 | AR27: 5 | BB27: 1 | BC27: 1 | BR27: 1 | BS27: 2 | BU27: 2 | BV27: 9960 | BW27: M | BX27: M | BZ27: ADM | CF27: 40.416667
B28: AAS-084 | D28: variant | E28: A | G28: AAS-085 | H28: AAS-010 | I28: D57412 BZ380 | J28: IRM-093175 | K28: MBR FLOOR SIDE INNER LH | L28: 1 | M28: 3000 | O28: =+M28+N28 -> 3000 | P28: =+O28/$H$18 -> 150 | Q28: =IF($H28=G28,SUMIF($H:$H,H28,$P:$P),P28) -> 150 | R28: =Q28*10%+Q28 -> 165 | S28: 2 | T28: =IF(M28=0,"0",ROUNDUP(P28*S28/AG28,0)*AG28) -> 300 | U28: =IF($H28=G28,SUMIF($H:$H,H28,$T:$T),T28) -> 300 | V28: =IF(M28=0,"0",ROUND(P28/W28,1)) -> 2.5 | W28: 60 | X28: =ROUNDUP(T28/W28,0) -> 5 | AE28: I | AG28: 60 | AQ28: 5.7 | AR28: 5 | BC28: 1 | BD28: 1 | BE28: 1 | BR28: 1 | BS28: 3 | BU28: 3 | BV28: 14940 | BW28: M | BX28: M | BZ28: ADM | CF28: 40.416667
B29: AAS-084 | D29: variant | E29: A | G29: AAS-009- | H29: AAS-009 | I29: D57411 BZ110 | J29: IRM-093175 | K29: MEMBER FLOOR SIDE INNER RH | L29: 1 | M29: 700 | O29: =+M29+N29 -> 700 | P29: =+O29/$H$18 -> 35 | Q29: =IF($H29=G29,SUMIF($H:$H,H29,$P:$P),P29) -> 35 | R29: =Q29*10%+Q29 -> 38.5 | S29: 2 | T29: =IF(M29=0,"0",ROUNDUP(P29*S29/AG29,0)*AG29) -> 100 | U29: =IF($H29=G29,SUMIF($H:$H,H29,$T:$T),T29) -> 100 | V29: =IF(M29=0,"0",ROUND(P29/W29,1)) -> 0.7 | W29: 50 | X29: =ROUNDUP(T29/W29,0) -> 2 | AE29: I | AG29: 50 | AQ29: 5.7 | AR29: 5 | BD29: 1 | BE29: 1 | BR29: 1 | BS29: 2 | BU29: 2 | BV29: 2200 | BW29: C | BX29: C | BZ29: ADM | CF29: 34.416667
B30: AAS-084 | D30: variant | E30: A | G30: AAS-009 | H30: AAS-009 | I30: D57411 BZ110 | J30: IRM-093175 | K30: MEMBER FLOOR SIDE INNER RH | L30: 1 | M30: 700 | O30: =+M30+N30 -> 700 | P30: =+O30/$H$18 -> 35 | Q30: =IF($H30=G30,SUMIF($H:$H,H30,$P:$P),P30) -> 370 | R30: =Q30*10%+Q30 -> 407 | S30: 2 | T30: =IF(M30=0,"0",ROUNDUP(P30*S30/AG30,0)*AG30) -> 100 | U30: =IF($H30=G30,SUMIF($H:$H,H30,$T:$T),T30) -> 800 | V30: =IF(M30=0,"0",ROUND(P30/W30,1)) -> 0.7 | W30: 50 | X30: =ROUNDUP(T30/W30,0) -> 2 | AE30: I | AG30: 50 | AQ30: 5.7 | AR30: 5 | BC30: 1 | BD30: 1 | BE30: 1 | BR30: 1 | BS30: 3 | BU30: 3 | BV30: 3300 | BW30: C | BX30: C | BZ30: ADM | CF30: 34.416667
B31: AAS-084 | D31: variant | E31: A | G31: AAS-010- | H31: AAS-010 | I31: D57412 BZ150 | J31: IRM-093175 | K31: MEMBER FLOOR SIDE INNER LH | L31: 1 | M31: 700 | O31: =+M31+N31 -> 700 | P31: =+O31/$H$18 -> 35 | Q31: =IF($H31=G31,SUMIF($H:$H,H31,$P:$P),P31) -> 35 | R31: =Q31*10%+Q31 -> 38.5 | S31: 2 | T31: =IF(M31=0,"0",ROUNDUP(P31*S31/AG31,0)*AG31) -> 100 | U31: =IF($H31=G31,SUMIF($H:$H,H31,$T:$T),T31) -> 100 | V31: =IF(M31=0,"0",ROUND(P31/W31,1)) -> 0.7 | W31: 50 | X31: =ROUNDUP(T31/W31,0) -> 2 | AE31: I | AG31: 50 | AQ31: 5.7 | AR31: 5 | BB31: 1 | BC31: 1 | BR31: 1 | BS31: 2 | BU31: 2 | BV31: 2200 | BW31: C | BX31: C | BZ31: ADM | CF31: 34.416667
B32: AAS-084 | D32: variant | E32: A | G32: AAS-010 | H32: AAS-010 | I32: D57412 BZ150 | J32: IRM-093175 | K32: MEMBER FLOOR SIDE INNER LH | L32: 1 | M32: 700 | O32: =+M32+N32 -> 700 | P32: =+O32/$H$18 -> 35 | Q32: =IF($H32=G32,SUMIF($H:$H,H32,$P:$P),P32) -> 370 | R32: =Q32*10%+Q32 -> 407 | S32: 2 | T32: =IF(M32=0,"0",ROUNDUP(P32*S32/AG32,0)*AG32) -> 100 | U32: =IF($H32=G32,SUMIF($H:$H,H32,$T:$T),T32) -> 800 | V32: =IF(M32=0,"0",ROUND(P32/W32,1)) -> 0.7 | W32: 50 | X32: =ROUNDUP(T32/W32,0) -> 2 | AE32: I | AG32: 50 | AQ32: 5.7 | AR32: 5 | BC32: 1 | BD32: 1 | BE32: 1 | BR32: 1 | BS32: 3 | BU32: 3 | BV32: 3300 | BW32: C | BX32: C | BZ32: ADM | CF32: 34.416667
B33: AAS-034 | E33: A | G33: AAS-034 | H33: AAS-034 | I33: D61231 BZ160 | J33: IRM-111401 | K33: RAIL ROOF SIDE INNER RH | L33: 1 | M33: 3675 | O33: =+M33+N33 -> 3675 | P33: =+O33/$H$18 -> 183.75 | Q33: =IF($H33=G33,SUMIF($H:$H,H33,$P:$P),P33) -> 367.5 | R33: =Q33*10%+Q33 -> 404.25 | S33: 2 | T33: =IF(M33=0,"0",ROUNDUP(P33*S33/AG33,0)*AG33) -> 720 | U33: =IF($H33=G33,SUMIF($H:$H,H33,$T:$T),T33) -> 1440 | V33: =IF(M33=0,"0",ROUND(P33/W33,1)) -> 7.4 | W33: 25 | X33: =ROUNDUP(T33/W33,0) -> 29 | AE33: I | AG33: 360 | AQ33: 6.5 | AR33: 5 | BB33: 1 | BR33: 1 | BS33: 1 | BU33: 1 | BV33: 6000 | BW33: M | BX33: M | BZ33: ADM | CF33: 48
B34: AAS-034 | E34: A | G34: AAS-035 | H34: AAS-034 | I34: D61232 BZ160 | J34: IRM-111401 | K34: RAIL ROOF SIDE INNER LH | L34: 1 | M34: 3675 | O34: =+M34+N34 -> 3675 | P34: =+O34/$H$18 -> 183.75 | Q34: =IF($H34=G34,SUMIF($H:$H,H34,$P:$P),P34) -> 183.75 | R34: =Q34*10%+Q34 -> 202.125 | S34: 2 | T34: =IF(M34=0,"0",ROUNDUP(P34*S34/AG34,0)*AG34) -> 720 | U34: =IF($H34=G34,SUMIF($H:$H,H34,$T:$T),T34) -> 720 | V34: =IF(M34=0,"0",ROUND(P34/W34,1)) -> 7.4 | W34: 25 | X34: =ROUNDUP(T34/W34,0) -> 29 | AE34: I | AG34: 360 | AQ34: 6.5 | AR34: 5 | BB34: 1 | BR34: 1 | BS34: 1 | BU34: 1 | BV34: 6000 | BW34: M | BX34: M | BZ34: ADM | CF34: 48
B35: AAS-054 | D35: variant | E35: A-D | G35: AAS-054 BLK | H35: AAS-054 | I35: D58213 BZ130 | J35: VRM-090474 | K35: REINF CTR FLOOR PANEL | L35: 1 | M35: 5540 | O35: =+M35+N35 -> 5540 | P35: =+O35/$H$18 -> 277 | Q35: =IF($H35=G35,SUMIF($H:$H,H35,$P:$P),P35) -> 277 | R35: =Q35*10%+Q35 -> 304.7 | S35: 2 | T35: =IF(M35=0,"0",ROUNDUP(P35*S35/AG35,0)*AG35) -> 720 | U35: =IF($H35=G35,SUMIF($H:$H,H35,$T:$T),T35) -> 720 | V35: =IF(M35=0,"0",ROUND(P35/W35,1)) -> 2.8 | W35: 100 | X35: =ROUNDUP(T35/W35,0) -> 8 | AE35: KHS | AG35: 360 | AQ35: 6 | AR35: 5 | BB35: 1 | BC35: 1 | BD35: 1 | BE35: 1 | BQ35: 1 | BR35: 1 | BS35: 4 | BU35: 4 | BV35: 31640 | BW35: M | BX35: M | BZ35: ADM | CF35: 91.333333
B36: AAS-054 | D36: variant | E36: A-D | G36: AAS-054 FNS | H36: AAS-054 | I36: D58213 BZ130 | J36: VRM-090474 | K36: REINF CTR FLOOR PANEL | L36: 1 | M36: 5540 | O36: =+M36+N36 -> 5540 | P36: =+O36/$H$18 -> 277 | Q36: =IF($H36=G36,SUMIF($H:$H,H36,$P:$P),P36) -> 277 | R36: =Q36*10%+Q36 -> 304.7 | S36: 2 | T36: =IF(M36=0,"0",ROUNDUP(P36*S36/AG36,0)*AG36) -> 720 | U36: =IF($H36=G36,SUMIF($H:$H,H36,$T:$T),T36) -> 720 | V36: =IF(M36=0,"0",ROUND(P36/W36,1)) -> 2.8 | W36: 100 | X36: =ROUNDUP(T36/W36,0) -> 8 | AE36: R | AG36: 180 | AQ36: 6 | AR36: 5 | BB36: 1 | BC36: 1 | BD36: 1 | BE36: 1 | BN36: 1 | BO36: 1 | BP36: 1 | BR36: 1 | BS36: 4 | BU36: 4 | BV36: 31640 | BW36: M | BX36: M | BZ36: ADM | CF36: 91.333333
B37: AAS-054 | D37: variant | E37: A | G37: AAS-082 | H37: AAS-054 | I37: DV58213 BZ150 | J37: VRM-090474 | K37: REINF CTR FLOOR PANEL | L37: 1 | M37: 1440 | O37: =+M37+N37 -> 1440 | P37: =+O37/$H$18 -> 72 | Q37: =IF($H37=G37,SUMIF($H:$H,H37,$P:$P),P37) -> 72 | R37: =Q37*10%+Q37 -> 79.2 | S37: 2 | T37: =IF(M37=0,"0",ROUNDUP(P37*S37/AG37,0)*AG37) -> 180 | U37: =IF($H37=G37,SUMIF($H:$H,H37,$T:$T),T37) -> 180 | V37: =IF(M37=0,"0",ROUND(P37/W37,1)) -> 1.2 | W37: 60 | X37: =ROUNDUP(T37/W37,0) -> 3 | AE37: R | AG37: 180 | AQ37: 5.7 | AR37: 5 | BB37: 1 | BC37: 1 | BD37: 1 | BE37: 1 | BR37: 1 | BS37: 4 | BU37: 4 | BV37: 10560 | BW37: C | BX37: C | BZ37: ADM | CF37: 85.333333
B38: AAS-054 | D38: variant | E38: A | G38: AAS-083 | H38: AAS-054 | I38: DV58213 BZ160 | J38: VRM-090474 | K38: REINF CTR FLOOR PANEL | L38: 1 | M38: 1620 | O38: =+M38+N38 -> 1620 | P38: =+O38/$H$18 -> 81 | Q38: =IF($H38=G38,SUMIF($H:$H,H38,$P:$P),P38) -> 81 | R38: =Q38*10%+Q38 -> 89.1 | S38: 2 | T38: =IF(M38=0,"0",ROUNDUP(P38*S38/AG38,0)*AG38) -> 180 | U38: =IF($H38=G38,SUMIF($H:$H,H38,$T:$T),T38) -> 180 | V38: =IF(M38=0,"0",ROUND(P38/W38,1)) -> 1.4 | W38: 60 | X38: =ROUNDUP(T38/W38,0) -> 3 | AE38: R | AG38: 180 | AQ38: 5.7 | AR38: 5 | BB38: 1 | BC38: 1 | BD38: 1 | BE38: 1 | BR38: 1 | BS38: 4 | BU38: 4 | BV38: 9360 | BW38: C | BX38: C | BZ38: ADM | CF38: 85.333333
B39: AAS-058 | C39: A-B | D39: SEP | E39: A | G39: AAS-058 | H39: AAS-058/59 | I39: D61343 BZ180 | J39: VRM-090127 | K39: PILLAR CTR BODY INNER RH | L39: 1 | M39: 5550 | O39: =+M39+N39 -> 5550 | P39: =+O39/$H$18 -> 277.5 | Q39: =IF($H39=G39,SUMIF($H:$H,H39,$P:$P),P39) -> 277.5 | R39: =Q39*10%+Q39 -> 305.25 | S39: 2 | T39: =IF(M39=0,"0",ROUNDUP(P39*S39/AG39,0)*AG39) -> 600 | U39: =IF($H39=G39,SUMIF($H:$H,H39,$T:$T),T39) -> 600 | V39: =IF(M39=0,"0",ROUND(P39/W39,1)) -> 5.6 | W39: 50 | X39: =ROUNDUP(T39/W39,0) -> 12 | AE39: D2 | AG39: 200 | AQ39: 6.3 | AR39: 5 | BC39: 1 | BD39: 1 | BE39: 1 | BF39: 1 | BG39: 1 | BH39: 1 | BN39: 1 | BO39: 1 | BP39: 1 | BR39: 1 | BS39: 3 | BU39: 3 | BV39: 23400 | BW39: M | BX39: M | BZ39: ADM | CF39: 57.166667
B40: AAS-058 | C40: A-B | D40: SEP | E40: A | G40: AAS-059 | H40: AAS-058 | I40: D61344 BZ190 | J40: VRM-090127 | K40: PILLAR CTR BODY INNER LH | L40: 1 | M40: 5550 | O40: =+M40+N40 -> 5550 | P40: =+O40/$H$18 -> 277.5 | Q40: =IF($H40=G40,SUMIF($H:$H,H40,$P:$P),P40) -> 277.5 | R40: =Q40*10%+Q40 -> 305.25 | S40: 2 | T40: =IF(M40=0,"0",ROUNDUP(P40*S40/AG40,0)*AG40) -> 600 | U40: =IF($H40=G40,SUMIF($H:$H,H40,$T:$T),T40) -> 600 | V40: =IF(M40=0,"0",ROUND(P40/W40,1)) -> 5.6 | W40: 50 | X40: =ROUNDUP(T40/W40,0) -> 12 | AE40: D2 | AG40: 200 | AQ40: 6.3 | AR40: 5 | BC40: 1 | BD40: 1 | BE40: 1 | BR40: 1 | BS40: 3 | BU40: 3 | BV40: 23400 | BW40: C | BX40: C | BZ40: ADM | CF40: 57.166667
B41: AAS-074 | D41: variant | E41: A | G41: AAS-074 | H41: AAS-074 | I41: D58213-BZ190 | J41: IRM-046703 | K41: REINF CTR FLOOR PANEL | L41: 1 | M41: 180 | O41: =+M41+N41 -> 180 | P41: =+O41/$H$18 -> 9 | Q41: =IF($H41=G41,SUMIF($H:$H,H41,$P:$P),P41) -> 40.5 | R41: =Q41*10%+Q41 -> 44.55 | S41: 14 | T41: =IF(M41=0,"0",ROUNDUP(P41*S41/AG41,0)*AG41) -> 180 | U41: =IF($H41=G41,SUMIF($H:$H,H41,$T:$T),T41) -> 420 | V41: =IF(M41=0,"0",ROUND(P41/W41,1)) -> 0.2 | W41: 60 | X41: =ROUNDUP(T41/W41,0) -> 3 | AE41: I | AG41: 60 | AQ41: 5.7 | AR41: 5 | BB41: 1 | BC41: 1 | BD41: 1 | BE41: 1 | BR41: 1 | BS41: 4 | BU41: 4 | BV41: 360 | BW41: M | BX41: M | BZ41: ADM | CF41: 15.5
B42: AAS-074 | D42: variant | E42: A | G42: AAS-075 | H42: AAS-074 | I42: D58213-BZ180 | J42: IRM-046703 | K42: REINF CTR FLOOR PANEL | L42: 1 | M42: 630 | O42: =+M42+N42 -> 630 | P42: =+O42/$H$18 -> 31.5 | Q42: =IF($H42=G42,SUMIF($H:$H,H42,$P:$P),P42) -> 31.5 | R42: =Q42*10%+Q42 -> 34.65 | S42: 7 | T42: =IF(M42=0,"0",ROUNDUP(P42*S42/AG42,0)*AG42) -> 240 | U42: =IF($H42=G42,SUMIF($H:$H,H42,$T:$T),T42) -> 240 | V42: =IF(M42=0,"0",ROUND(P42/W42,1)) -> 0.5 | W42: 60 | X42: =ROUNDUP(T42/W42,0) -> 4 | AE42: I | AG42: 60 | AQ42: 5.7 | AR42: 5 | BB42: 1 | BC42: 1 | BD42: 1 | BE42: 1 | BR42: 1 | BS42: 4 | BU42: 4 | BV42: 4320 | BW42: M | BX42: M | BZ42: ADM | CF42: 41.5
E43: A | G43: G-002 | H43: G-005 | I43: D61162 BZ081G2 | J43: IRM-090551 | K43: PILLAR FR BODY INNER LH | L43: 1 | M43: 300 | O43: =+M43+N43 -> 300 | P43: =+O43/$H$18 -> 15 | Q43: =IF($H43=G43,SUMIF($H:$H,H43,$P:$P),P43) -> 15 | R43: =Q43*10%+Q43 -> 16.5 | S43: 4 | T43: =IF(M43=0,"0",ROUNDUP(P43*S43/AG43,0)*AG43) -> 180 | U43: =IF($H43=G43,SUMIF($H:$H,H43,$T:$T),T43) -> 180 | V43: =IF(M43=0,"0",ROUND(P43/W43,1)) -> 0.3 | W43: 60 | X43: =ROUNDUP(T43/W43,0) -> 3 | AE43: D | AG43: 180 | AQ43: 6.3 | AR43: 6 | BB43: 1 | BN43: 1 | BO43: 1 | BP43: 1 | BR43: 1 | BS43: 1 | BU43: 1 | BV43: 900 | BW43: M | BX43: M | BZ43: ADM | CF43: 22
E44: A | G44: G-002 FNS | H44: G-005 | I44: D61162 BZ081G2 | J44: IRM-090551 | K44: PILLAR FR BODY INNER LH | L44: 1 | M44: 300 | O44: =+M44+N44 -> 300 | P44: =+O44/$H$18 -> 15 | Q44: =IF($H44=G44,SUMIF($H:$H,H44,$P:$P),P44) -> 15 | R44: =Q44*10%+Q44 -> 16.5 | S44: 4 | T44: =IF(M44=0,"0",ROUNDUP(P44*S44/AG44,0)*AG44) -> 180 | U44: =IF($H44=G44,SUMIF($H:$H,H44,$T:$T),T44) -> 180 | V44: =IF(M44=0,"0",ROUND(P44/W44,1)) -> 0.3 | W44: 60 | X44: =ROUNDUP(T44/W44,0) -> 3 | AE44: D | AG44: 180 | AQ44: 6.3 | AR44: 6 | BB44: 1 | BN44: 1 | BO44: 1 | BP44: 1 | BR44: 1 | BS44: 1 | BU44: 1 | BV44: 900 | BW44: M | BX44: M | BZ44: ADM | CF44: 22
B45: G-005 | E45: A | G45: G-009 WIP | H45: G-005 | I45: D61161 BZ131G9 | J45: IRM-090551 | K45: PILLAR FR BODY INNER RH | L45: 1 | M45: 60 | O45: =+M45+N45 -> 60 | P45: =+O45/$H$18 -> 3 | Q45: =IF($H45=G45,SUMIF($H:$H,H45,$P:$P),P45) -> 3 | R45: =Q45*10%+Q45 -> 3.3 | S45: 4 | T45: =IF(M45=0,"0",ROUNDUP(P45*S45/AG45,0)*AG45) -> 180 | U45: =IF($H45=G45,SUMIF($H:$H,H45,$T:$T),T45) -> 180 | V45: =IF(M45=0,"0",ROUND(P45/W45,1)) -> 0.1 | W45: 60 | X45: =ROUNDUP(T45/W45,0) -> 3 | AE45: KHS | AG45: 180 | AQ45: 6.3 | AR45: 6 | BB45: 1 | BN45: 1 | BO45: 1 | BP45: 1 | BR45: 1 | BS45: 1 | BU45: 1 | BV45: 360 | BW45: C | BX45: C | BZ45: ADM | CF45: 22
E46: A | G46: G-009 FNS | H46: G-005 | I46: D61161 BZ131G9 | J46: IRM-090551 | K46: PILLAR FR BODY INNER RH | L46: 1 | M46: 60 | O46: =+M46+N46 -> 60 | P46: =+O46/$H$18 -> 3 | Q46: =IF($H46=G46,SUMIF($H:$H,H46,$P:$P),P46) -> 3 | R46: =Q46*10%+Q46 -> 3.3 | S46: 4 | T46: =IF(M46=0,"0",ROUNDUP(P46*S46/AG46,0)*AG46) -> 180 | U46: =IF($H46=G46,SUMIF($H:$H,H46,$T:$T),T46) -> 180 | V46: =IF(M46=0,"0",ROUND(P46/W46,1)) -> 0.1 | W46: 60 | X46: =ROUNDUP(T46/W46,0) -> 3 | AE46: D | AG46: 180 | AQ46: 6.3 | AR46: 6 | BB46: 1 | BN46: 1 | BO46: 1 | BP46: 1 | BR46: 1 | BS46: 1 | BU46: 1 | BV46: 360 | BW46: C | BX46: C | BZ46: ADM | CF46: 22
B47: G-005 | E47: A | G47: G-003 WIP | H47: G-005 | I47: D61161 BZ091G3 | J47: IRM-090551 | K47: PILLAR FR BODY INNER RH | L47: 1 | M47: 960 | O47: =+M47+N47 -> 960 | P47: =+O47/$H$18 -> 48 | Q47: =IF($H47=G47,SUMIF($H:$H,H47,$P:$P),P47) -> 48 | R47: =Q47*10%+Q47 -> 52.8 | S47: 4 | T47: =IF(M47=0,"0",ROUNDUP(P47*S47/AG47,0)*AG47) -> 360 | U47: =IF($H47=G47,SUMIF($H:$H,H47,$T:$T),T47) -> 360 | V47: =IF(M47=0,"0",ROUND(P47/W47,1)) -> 0.8 | W47: 60 | X47: =ROUNDUP(T47/W47,0) -> 6 | AE47: KHS | AG47: 180 | AQ47: 6.3 | AR47: 6 | BB47: 1 | BN47: 1 | BO47: 1 | BP47: 1 | BR47: 1 | BS47: 1 | BU47: 1 | BV47: 2340 | BW47: C | BX47: C | BZ47: ADM | CF47: 35
E48: A | G48: G-003 FNS | H48: G-005 | I48: D61161 BZ091G3 | J48: IRM-090551 | K48: PILLAR FR BODY INNER RH | L48: 1 | M48: 960 | O48: =+M48+N48 -> 960 | P48: =+O48/$H$18 -> 48 | Q48: =IF($H48=G48,SUMIF($H:$H,H48,$P:$P),P48) -> 48 | R48: =Q48*10%+Q48 -> 52.8 | S48: 4 | T48: =IF(M48=0,"0",ROUNDUP(P48*S48/AG48,0)*AG48) -> 360 | U48: =IF($H48=G48,SUMIF($H:$H,H48,$T:$T),T48) -> 360 | V48: =IF(M48=0,"0",ROUND(P48/W48,1)) -> 0.8 | W48: 60 | X48: =ROUNDUP(T48/W48,0) -> 6 | AE48: D | AG48: 180 | AQ48: 6.3 | AR48: 6 | BB48: 1 | BN48: 1 | BO48: 1 | BP48: 1 | BR48: 1 | BS48: 1 | BU48: 1 | BV48: 2340 | BW48: C | BX48: C | BZ48: ADM | CF48: 35
B49: G-005 | E49: A | G49: G-004 WIP | H49: G-005 | I49: D61162 BZ091G4 | J49: IRM-090551 | K49: PILLAR FR BODY INNER LH | L49: 1 | M49: 960 | O49: =+M49+N49 -> 960 | P49: =+O49/$H$18 -> 48 | Q49: =IF($H49=G49,SUMIF($H:$H,H49,$P:$P),P49) -> 48 | R49: =Q49*10%+Q49 -> 52.8 | S49: 4 | T49: =IF(M49=0,"0",ROUNDUP(P49*S49/AG49,0)*AG49) -> 360 | U49: =IF($H49=G49,SUMIF($H:$H,H49,$T:$T),T49) -> 360 | V49: =IF(M49=0,"0",ROUND(P49/W49,1)) -> 0.8 | W49: 60 | X49: =ROUNDUP(T49/W49,0) -> 6 | AE49: KHS | AG49: 180 | AQ49: 6.3 | AR49: 6 | BB49: 1 | BN49: 1 | BO49: 1 | BP49: 1 | BR49: 1 | BS49: 1 | BU49: 1 | BV49: 2640 | BW49: M | BX49: M | BZ49: ADM | CF49: 35
E50: A | G50: G-004 FNS | H50: G-005 | I50: D61162 BZ091G4 | J50: IRM-090551 | K50: PILLAR FR BODY INNER LH | L50: 1 | M50: 960 | O50: =+M50+N50 -> 960 | P50: =+O50/$H$18 -> 48 | Q50: =IF($H50=G50,SUMIF($H:$H,H50,$P:$P),P50) -> 48 | R50: =Q50*10%+Q50 -> 52.8 | S50: 4 | T50: =IF(M50=0,"0",ROUNDUP(P50*S50/AG50,0)*AG50) -> 360 | U50: =IF($H50=G50,SUMIF($H:$H,H50,$T:$T),T50) -> 360 | V50: =IF(M50=0,"0",ROUND(P50/W50,1)) -> 0.8 | W50: 60 | X50: =ROUNDUP(T50/W50,0) -> 6 | AE50: D | AG50: 180 | AQ50: 6.3 | AR50: 6 | BB50: 1 | BN50: 1 | BO50: 1 | BP50: 1 | BR50: 1 | BS50: 1 | BU50: 1 | BV50: 2640 | BW50: M | BX50: M | BZ50: ADM | CF50: 35
B51: G-005 | E51: A | G51: G-003N WIP | H51: G-005 | L51: 1 | M51: 960 | O51: =+M51+N51 -> 960 | P51: =+O51/$H$18 -> 48 | Q51: =IF($H51=G51,SUMIF($H:$H,H51,$P:$P),P51) -> 48 | R51: =Q51*10%+Q51 -> 52.8 | S51: 4 | T51: =IF(M51=0,"0",ROUNDUP(P51*S51/AG51,0)*AG51) -> 360 | U51: =IF($H51=G51,SUMIF($H:$H,H51,$T:$T),T51) -> 360 | V51: =IF(M51=0,"0",ROUND(P51/W51,1)) -> 0.8 | W51: 60 | X51: =ROUNDUP(T51/W51,0) -> 6 | AE51: KHS | AG51: 180 | AQ51: 6.5 | AR51: 5 | BB51: 1 | BF51: 1 | BG51: 1 | BH51: 1 | BI51: 1 | BN51: 1 | BO51: 1 | BP51: 1 | BQ51: 1 | BR51: 3 | BS51: 3 | BU51: 1 | BV51: 2340 | BW51: C | BX51: C | BZ51: ADM | CF51: 35
B52: G-005 | E52: A | G52: G-003N WIP1 | H52: G-005 | L52: 1 | M52: 960 | O52: =+M52+N52 -> 960 | P52: =+O52/$H$18 -> 48 | Q52: =IF($H52=G52,SUMIF($H:$H,H52,$P:$P),P52) -> 48 | R52: =Q52*10%+Q52 -> 52.8 | S52: 4 | T52: =IF(M52=0,"0",ROUNDUP(P52*S52/AG52,0)*AG52) -> 360 | U52: =IF($H52=G52,SUMIF($H:$H,H52,$T:$T),T52) -> 360 | V52: =IF(M52=0,"0",ROUND(P52/W52,1)) -> 0.8 | W52: 60 | X52: =ROUNDUP(T52/W52,0) -> 6 | AE52: D | AG52: 180 | AQ52: 6.5 | AR52: 5 | BB52: 1 | BR52: 1 | BS52: 1 | BU52: 1 | BV52: 2340 | BW52: C | BX52: C | BZ52: ADM | CF52: 35
E53: A | G53: G-003N FNS | H53: G-005 | L53: 1 | M53: 960 | O53: =+M53+N53 -> 960 | P53: =+O53/$H$18 -> 48 | Q53: =IF($H53=G53,SUMIF($H:$H,H53,$P:$P),P53) -> 48 | R53: =Q53*10%+Q53 -> 52.8 | S53: 4 | T53: =IF(M53=0,"0",ROUNDUP(P53*S53/AG53,0)*AG53) -> 360 | U53: =IF($H53=G53,SUMIF($H:$H,H53,$T:$T),T53) -> 360 | V53: =IF(M53=0,"0",ROUND(P53/W53,1)) -> 0.8 | W53: 60 | X53: =ROUNDUP(T53/W53,0) -> 6 | AE53: D | AG53: 180 | AQ53: 6.5 | AR53: 5 | BB53: 1 | BI53: 1 | BQ53: 1 | BR53: 3 | BS53: 3 | BU53: 1 | BV53: 2340 | BW53: C | BX53: C | BZ53: ADM | CF53: 35
E54: A | G54: G-003N FNS1 | H54: G-005 | L54: 1 | M54: 960 | O54: =+M54+N54 -> 960 | P54: =+O54/$H$18 -> 48 | Q54: =IF($H54=G54,SUMIF($H:$H,H54,$P:$P),P54) -> 48 | R54: =Q54*10%+Q54 -> 52.8 | S54: 4 | T54: =IF(M54=0,"0",ROUNDUP(P54*S54/AG54,0)*AG54) -> 360 | U54: =IF($H54=G54,SUMIF($H:$H,H54,$T:$T),T54) -> 360 | V54: =IF(M54=0,"0",ROUND(P54/W54,1)) -> 0.8 | W54: 60 | X54: =ROUNDUP(T54/W54,0) -> 6 | AE54: D | AG54: 180 | AQ54: 6.5 | AR54: 5 | BB54: 1 | BI54: 1 | BR54: 1 | BS54: 1 | BU54: 1 | BV54: 2340 | BW54: C | BX54: C | BZ54: ADM | CF54: 35
...

Sheet master untuk shift 1
H3: update
D4: MASTER UNTUK PEMBUATAN PO
D6: NO | E6: JOB MASTER SCHEDULE | F6: JOB NO UNTUK PO | G6: QTY | H6: LINE
D7: 1 | E7: NX-2892 | F7: NX-2892 | G7: =SUMIF('Shift Pagi'!I:I,'master untuk shift 1'!E7,'Shift Pagi'!L:L) -> 0 | H7: PRESS-A | I7: =SUMIF('Shift Pagi'!I:I,'master untuk shift 1'!E7,'Shift Pagi'!L:L) -> 0
D8: 2 | E8: NX-2893 | F8: NX-2893 | G8: =SUMIF('Shift Pagi'!I:I,'master untuk shift 1'!E8,'Shift Pagi'!L:L) -> 0 | H8: PRESS-A | I8: =SUMIF('Shift Pagi'!I:I,'master untuk shift 1'!E8,'Shift Pagi'!L:L) -> 0
D9: 3 | E9: NX-0541 | F9: NX-0541 | G9: =SUMIF('Shift Pagi'!I:I,'master untuk shift 1'!E9,'Shift Pagi'!L:L) -> 0 | H9: PRESS-A | I9: =SUMIF('Shift Pagi'!I:I,'master untuk shift 1'!E9,'Shift Pagi'!L:L) -> 0
D10: 4 | E10: NX-0541 | F10: NX-4837 | G10: =SUMIF('Shift Pagi'!I:I,'master untuk shift 1'!E10,'Shift Pagi'!L:L) -> 0 | H10: PRESS-A | I10: =SUMIF('Shift Pagi'!I:I,'master untuk shift 1'!E10,'Shift Pagi'!L:L) -> 0
D11: 5 | E11: NX-2902 | F11: NX-2902 | G11: =SUMIF('Shift Pagi'!I:I,'master untuk shift 1'!E11,'Shift Pagi'!L:L) -> 0 | H11: PRESS-A | I11: =SUMIF('Shift Pagi'!I:I,'master untuk shift 1'!E11,'Shift Pagi'!L:L) -> 0
D12: 6 | E12: GT-2518 | F12: GT-2518 | G12: =SUMIF('Shift Pagi'!I:I,'master untuk shift 1'!E12,'Shift Pagi'!L:L) -> 175 | H12: PRESS-C | I12: =SUMIF('Shift Pagi'!I:I,'master untuk shift 1'!E12,'Shift Pagi'!L:L) -> 175
D13: 7 | E13: GT-2519 | F13: GT-2519 | G13: =SUMIF('Shift Pagi'!I:I,'master untuk shift 1'!E13,'Shift Pagi'!L:L) -> 100 | H13: PRESS-C | I13: =SUMIF('Shift Pagi'!I:I,'master untuk shift 1'!E13,'Shift Pagi'!L:L) -> 100
D14: 8 | E14: GT-2520 | F14: GT-2520 | G14: =SUMIF('Shift Pagi'!I:I,'master untuk shift 1'!E14,'Shift Pagi'!L:L) -> 25 | H14: PRESS-C | I14: =SUMIF('Shift Pagi'!I:I,'master untuk shift 1'!E14,'Shift Pagi'!L:L) -> 25
D15: 9 | E15: SC-0767 | F15: SC-0767 | G15: =SUMIF('Shift Pagi'!I:I,'master untuk shift 1'!E15,'Shift Pagi'!L:L) -> 0 | H15: PRESS-B | I15: =SUMIF('Shift Pagi'!I:I,'master untuk shift 1'!E15,'Shift Pagi'!L:L) -> 0
D16: 10 | E16: SC-0767 | F16: SC-0768 | G16: =SUMIF('Shift Pagi'!I:I,'master untuk shift 1'!E16,'Shift Pagi'!L:L) -> 0 | H16: PRESS-B | I16: =SUMIF('Shift Pagi'!I:I,'master untuk shift 1'!E16,'Shift Pagi'!L:L) -> 0
D17: 11 | E17: PB-017 | F17: PB-017 | G17: =SUMIF('Shift Pagi'!I:I,'master untuk shift 1'!E17,'Shift Pagi'!L:L) -> 0 | H17: PRESS-D | I17: =SUMIF('Shift Pagi'!I:I,'master untuk shift 1'!E17,'Shift Pagi'!L:L) -> 0
D18: 12 | E18: PB-070 | F18: PB-070 | G18: =SUMIF('Shift Pagi'!I:I,'master untuk shift 1'!E18,'Shift Pagi'!L:L) -> 0 | H18: PRESS-B | I18: =SUMIF('Shift Pagi'!I:I,'master untuk shift 1'!E18,'Shift Pagi'!L:L) -> 0
... D82: 76 | E82: IB-010 | F82: IB-010 | G82: =SUMIF('Shift Pagi'!I:I,'master untuk shift 1'!E82,'Shift Pagi'!L:L) -> 0 | H82: PRESS-D | I82: =SUMIF('Shift Pagi'!I:I,'master untuk shift 1'!E82,'Shift Pagi'!L:L) -> 0
D83: 77 | E83: NA-053 FNS | F83: NA-053/T213/T213E | G83: =SUMIF('Shift Pagi'!I:I,'master untuk shift 1'!E83,'Shift Pagi'!L:L) -> 400 | H83: PRESS-B | I83: =SUMIF('Shift Pagi'!I:I,'master untuk shift 1'!E83,'Shift Pagi'!L:L) -> 400 | K83: T213
D84: 78 | E84: NA-053 FNS | F84: NA-056/T214/T214E | G84: =SUMIF('Shift Pagi'!I:I,'master untuk shift 1'!E84,'Shift Pagi'!L:L) -> 400 | H84: PRESS-B | I84: =SUMIF('Shift Pagi'!I:I,'master untuk shift 1'!E84,'Shift Pagi'!L:L) -> 400 | K84: T213E
D85: 79 | E85: AE-0090 FNS | F85: AE-0090 | G85: =SUMIF('Shift Pagi'!I:I,'master untuk shift 1'!E85,'Shift Pagi'!L:L) -> 0 | H85: PRESS-B | I85: =SUMIF('Shift Pagi'!I:I,'master untuk shift 1'!E85,'Shift Pagi'!L:L) -> 0 | K85: NA-053
D86: 80 | E86: AE-0091 FNS | F86: AE-0091 | G86: =SUMIF('Shift Pagi'!I:I,'master untuk shift 1'!E86,'Shift Pagi'!L:L) -> 1000 | H86: PRESS-B | I86: =SUMIF('Shift Pagi'!I:I,'master untuk shift 1'!E86,'Shift Pagi'!L:L) -> 1000 | K86: T227
D87: 81 | E87: AES-001 FNS | F87: AES-001 | G87: =SUMIF('Shift Pagi'!I:I,'master untuk shift 1'!E87,'Shift Pagi'!L:L) -> 0 | H87: PRESS-B | I87: =SUMIF('Shift Pagi'!I:I,'master untuk shift 1'!E87,'Shift Pagi'!L:L) -> 0 | K87: NA-054
D88: 82 | E88: AES-048 FNS | F88: AES-048 | G88: =SUMIF('Shift Pagi'!I:I,'master untuk shift 1'!E88,'Shift Pagi'!L:L) -> 500 | H88: PRESS-B | I88: =SUMIF('Shift Pagi'!I:I,'master untuk shift 1'!E88,'Shift Pagi'!L:L) -> 500 | K88: T231
D89: 83 | E89: AES-002 FNS | F89: AES-002 | G89: =SUMIF('Shift Pagi'!I:I,'master untuk shift 1'!E89,'Shift Pagi'!L:L) -> 0 | H89: PRESS-B | I89: =SUMIF('Shift Pagi'!I:I,'master untuk shift 1'!E89,'Shift Pagi'!L:L) -> 0 | K89: NA-055
D90: 84 | E90: AES-006 FNS | F90: AES-006 | G90: =SUMIF('Shift Pagi'!I:I,'master untuk shift 1'!E90,'Shift Pagi'!L:L) -> 0 | H90: PRESS-B | I90: =SUMIF('Shift Pagi'!I:I,'master untuk shift 1'!E90,'Shift Pagi'!L:L) -> 0 | K90: T214
D91: 85 | E91: AES-016 FNS | F91: AES-016 | G91: =SUMIF('Shift Pagi'!I:I,'master untuk shift 1'!E91,'Shift Pagi'!L:L) -> 500 | H91: PRESS-B | I91: =SUMIF('Shift Pagi'!I:I,'master untuk shift 1'!E91,'Shift Pagi'!L:L) -> 500 | K91: NA-056
D92: 86 | E92: AES-017 FNS | F92: AES-017 | G92: =SUMIF('Shift Pagi'!I:I,'master untuk shift 1'!E92,'Shift Pagi'!L:L) -> 500 | H92: PRESS-B | I92: =SUMIF('Shift Pagi'!I:I,'master untuk shift 1'!E92,'Shift Pagi'!L:L) -> 500 | K92: T214
D93: 87 | E93: IB-050 | F93: IB-050 | G93: =SUMIF('Shift Pagi'!I:I,'master untuk shift 1'!E93,'Shift Pagi'!L:L) -> 0 | H93: PRESS-Ds | I93: =SUMIF('Shift Pagi'!I:I,'master untuk shift 1'!E93,'Shift Pagi'!L:L) -> 0
D94: 88 | E94: IB-077 | F94: IB-077 | G94: =SUMIF('Shift Pagi'!I:I,'master untuk shift 1'!E94,'Shift Pagi'!L:L) -> 0 | H94: PRESS-Ds | I94: =SUMIF('Shift Pagi'!I:I,'master untuk shift 1'!E94,'Shift Pagi'!L:L) -> 0
D95: 89 | E95: G-013- | F95: G-014 | G95: =SUMIF('Shift Pagi'!I:I,'master untuk shift 1'!E95,'Shift Pagi'!L:L) -> 0 | H95: PRESS-Bs | I95: =SUMIF('Shift Pagi'!I:I,'master untuk shift 1'!E95,'Shift Pagi'!L:L) -> 0
D96: 90 | E96: G-015- | F96: G-016 | G96: =SUMIF('Shift Pagi'!I:I,'master untuk shift 1'!E96,'Shift Pagi'!L:L) -> 0 | H96: PRESS-Bs | I96: =SUMIF('Shift Pagi'!I:I,'master untuk shift 1'!E96,'Shift Pagi'!L:L) -> 0
D97: 91 | E97: G-013- | F97: G-013 | G97: =SUMIF('Shift Pagi'!I:I,'master untuk shift 1'!E97,'Shift Pagi'!L:L) -> 0 | H97: PRESS-Bs | I97: =SUMIF('Shift Pagi'!I:I,'master untuk shift 1'!E97,'Shift Pagi'!L:L) -> 0
D98: 92 | E98: G-015- | F98: G-015 | G98: =SUMIF('Shift Pagi'!I:I,'master untuk shift 1'!E98,'Shift Pagi'!L:L) -> 0 | H98: PRESS-Bs | I98: =SUMIF('Shift Pagi'!I:I,'master untuk shift 1'!E98,'Shift Pagi'!L:L) -> 0
D99: 93 | E99: G-013 | F99: G-014 | G99: =SUMIF('Shift Pagi'!I:I,'master untuk shift 1'!E99,'Shift Pagi'!L:L) -> 0 | H99: PRESS-Bs | I99: =SUMIF('Shift Pagi'!I:I,'master untuk shift 1'!E99,'Shift Pagi'!L:L) -> 0
D100: 94 | E100: G-015 | F100: G-016 | G100: =SUMIF('Shift Pagi'!I:I,'master untuk shift 1'!E100,'Shift Pagi'!L:L) -> 0 | H100: PRESS-Bs | I100: =SUMIF('Shift Pagi'!I:I,'master untuk shift 1'!E100,'Shift Pagi'!L:L) -> 0
D101: 95 | E101: G-013 | F101: G-013 | G101: =SUMIF('Shift Pagi'!I:I,'master untuk shift 1'!E101,'Shift Pagi'!L:L) -> 0 | H101: PRESS-Bs | I101: =SUMIF('Shift Pagi'!I:I,'master untuk shift 1'!E101,'Shift Pagi'!L:L) -> 0
D102: 96 | E102: G-015 | F102: G-015 | G102: =SUMIF('Shift Pagi'!I:I,'master untuk shift 1'!E102,'Shift Pagi'!L:L) -> 0 | H102: PRESS-Bs | I102: =SUMIF('Shift Pagi'!I:I,'master untuk shift 1'!E102,'Shift Pagi'!L:L) -> 0
D103: 97 | E103: G-028 | F103: G-028 | G103: =SUMIF('Shift Pagi'!I:I,'master untuk shift 1'!E103,'Shift Pagi'!L:L) -> 0 | H103: PRESS-Bs | I103: =SUMIF('Shift Pagi'!I:I,'master untuk shift 1'!E103,'Shift Pagi'!L:L) -> 0
D104: 98 | E104: G-029 | F104: G-029 | G104: =SUMIF('Shift Pagi'!I:I,'master untuk shift 1'!E104,'Shift Pagi'!L:L) -> 0 | H104: PRESS-Bs | I104: =SUMIF('Shift Pagi'!I:I,'master untuk shift 1'!E104,'Shift Pagi'!L:L) -> 0
... D202: 196 | E202: AES-029 FNS | F202: AES-029 | G202: =SUMIF('Shift Pagi'!I:I,'master untuk shift 1'!E202,'Shift Pagi'!L:L) -> 180 | H202: PRESS-B | I202: =SUMIF('Shift Pagi'!I:I,'master untuk shift 1'!E202,'Shift Pagi'!L:L) -> 180
D203: 197 | E203: AES-029 FNS | F203: AES-034 | G203: =SUMIF('Shift Pagi'!I:I,'master untuk shift 1'!E203,'Shift Pagi'!L:L) -> 180 | H203: PRESS-B | I203: =SUMIF('Shift Pagi'!I:I,'master untuk shift 1'!E203,'Shift Pagi'!L:L) -> 180 | J203: 100
...

Sheet master untuk shift 2
D4: MASTER UNTUK PEMBUATAN PO
D6: NO | E6: JOB MASTER SCHEDULE | F6: JOB NO UNTUK PO | G6: QTY | H6: LINE
D7: 1 | E7: NX-2892 | F7: NX-2892 | G7: =SUMIF('Shift Malam'!I:I,'master untuk shift 2'!E7,'Shift Malam'!L:L) -> 0 | H7: PRESS-A | I7: =SUMIF('Shift Malam'!I:I,'master untuk shift 2'!E:E,'Shift Malam'!L:L) -> 0
D8: 2 | E8: NX-2893 | F8: NX-2893 | G8: =SUMIF('Shift Malam'!I:I,'master untuk shift 2'!E8,'Shift Malam'!L:L) -> 0 | H8: PRESS-A | I8: =SUMIF('Shift Malam'!I:I,'master untuk shift 2'!E:E,'Shift Malam'!L:L) -> 0
D9: 3 | E9: NX-0541 | F9: NX-0541 | G9: =SUMIF('Shift Malam'!I:I,'master untuk shift 2'!E9,'Shift Malam'!L:L) -> 0 | H9: PRESS-A | I9: =SUMIF('Shift Malam'!I:I,'master untuk shift 2'!E:E,'Shift Malam'!L:L) -> 0
D10: 4 | E10: NX-0541 | F10: NX-4837 | G10: =SUMIF('Shift Malam'!I:I,'master untuk shift 2'!E10,'Shift Malam'!L:L) -> 0 | H10: PRESS-A | I10: =SUMIF('Shift Malam'!I:I,'master untuk shift 2'!E:E,'Shift Malam'!L:L) -> 0
D11: 5 | E11: NX-2902 | F11: NX-2902 | G11: =SUMIF('Shift Malam'!I:I,'master untuk shift 2'!E11,'Shift Malam'!L:L) -> 0 | H11: PRESS-A | I11: =SUMIF('Shift Malam'!I:I,'master untuk shift 2'!E:E,'Shift Malam'!L:L) -> 0
D12: 6 | E12: GT-2518 | F12: GT-2518 | G12: =SUMIF('Shift Malam'!I:I,'master untuk shift 2'!E12,'Shift Malam'!L:L) -> 0 | H12: PRESS-C | I12: =SUMIF('Shift Malam'!I:I,'master untuk shift 2'!E:E,'Shift Malam'!L:L) -> 0
D13: 7 | E13: GT-2519 | F13: GT-2519 | G13: =SUMIF('Shift Malam'!I:I,'master untuk shift 2'!E13,'Shift Malam'!L:L) -> 0 | H13: PRESS-C | I13: =SUMIF('Shift Malam'!I:I,'master untuk shift 2'!E:E,'Shift Malam'!L:L) -> 0
D14: 8 | E14: GT-2520 | F14: GT-2520 | G14: =SUMIF('Shift Malam'!I:I,'master untuk shift 2'!E14,'Shift Malam'!L:L) -> 0 | H14: PRESS-C | I14: =SUMIF('Shift Malam'!I:I,'master untuk shift 2'!E:E,'Shift Malam'!L:L) -> 0
D15: 9 | E15: SC-0767 | F15: SC-0767 | G15: =SUMIF('Shift Malam'!I:I,'master untuk shift 2'!E15,'Shift Malam'!L:L) -> 0 | H15: PRESS-B | I15: =SUMIF('Shift Malam'!I:I,'master untuk shift 2'!E:E,'Shift Malam'!L:L) -> 0
D16: 10 | E16: SC-0767 | F16: SC-0768 | G16: =SUMIF('Shift Malam'!I:I,'master untuk shift 2'!E16,'Shift Malam'!L:L) -> 0 | H16: PRESS-B | I16: =SUMIF('Shift Malam'!I:I,'master untuk shift 2'!E:E,'Shift Malam'!L:L) -> 0
D17: 11 | E17: PB-017 | F17: PB-017 | G17: =SUMIF('Shift Malam'!I:I,'master untuk shift 2'!E17,'Shift Malam'!L:L) -> 0 | H17: PRESS-D | I17: =SUMIF('Shift Malam'!I:I,'master untuk shift 2'!E:E,'Shift Malam'!L:L) -> 0
D18: 12 | E18: PB-070 | F18: PB-070 | G18: =SUMIF('Shift Malam'!I:I,'master untuk shift 2'!E18,'Shift Malam'!L:L) -> 0 | H18: PRESS-B | I18: =SUMIF('Shift Malam'!I:I,'master untuk shift 2'!E:E,'Shift Malam'!L:L) -> 0
... D82: 76 | E82: IB-010 | F82: IB-010 | G82: =SUMIF('Shift Malam'!I:I,'master untuk shift 2'!E82,'Shift Malam'!L:L) -> 0 | H82: PRESS-D | I82: =SUMIF('Shift Malam'!I:I,'master untuk shift 2'!E:E,'Shift Malam'!L:L) -> 0
D83: 77 | E83: NA-053 FNS | F83: NA-053/T213/T213E | G83: =SUMIF('Shift Malam'!I:I,'master untuk shift 2'!E83,'Shift Malam'!L:L) -> 0 | H83: PRESS-B | I83: =SUMIF('Shift Malam'!I:I,'master untuk shift 2'!E:E,'Shift Malam'!L:L) -> 0 | K83: T213
D84: 78 | E84: NA-053 FNS | F84: NA-056/T214/T214E | G84: =SUMIF('Shift Malam'!I:I,'master untuk shift 2'!E84,'Shift Malam'!L:L) -> 0 | H84: PRESS-B | I84: =SUMIF('Shift Malam'!I:I,'master untuk shift 2'!E:E,'Shift Malam'!L:L) -> 0 | K84: T213E
D85: 79 | E85: AE-0090 FNS | F85: AE-0090 | G85: =SUMIF('Shift Malam'!I:I,'master untuk shift 2'!E85,'Shift Malam'!L:L) -> 0 | H85: PRESS-B | I85: =SUMIF('Shift Malam'!I:I,'master untuk shift 2'!E:E,'Shift Malam'!L:L) -> 0 | K85: NA-053
D86: 80 | E86: AE-0091 FNS | F86: AE-0091 | G86: =SUMIF('Shift Malam'!I:I,'master untuk shift 2'!E86,'Shift Malam'!L:L) -> 0 | H86: PRESS-B | I86: =SUMIF('Shift Malam'!I:I,'master untuk shift 2'!E:E,'Shift Malam'!L:L) -> 0 | K86: T227
D87: 81 | E87: AES-001 FNS | F87: AES-001 | G87: =SUMIF('Shift Malam'!I:I,'master untuk shift 2'!E87,'Shift Malam'!L:L) -> 0 | H87: PRESS-B | I87: =SUMIF('Shift Malam'!I:I,'master untuk shift 2'!E:E,'Shift Malam'!L:L) -> 0 | K87: NA-054
D88: 82 | E88: AES-048 FNS | F88: AES-048 | G88: =SUMIF('Shift Malam'!I:I,'master untuk shift 2'!E88,'Shift Malam'!L:L) -> 0 | H88: PRESS-B | I88: =SUMIF('Shift Malam'!I:I,'master untuk shift 2'!E:E,'Shift Malam'!L:L) -> 0 | K88: T231
D89: 83 | E89: AES-002 FNS | F89: AES-002 | G89: =SUMIF('Shift Malam'!I:I,'master untuk shift 2'!E89,'Shift Malam'!L:L) -> 0 | H89: PRESS-B | I89: =SUMIF('Shift Malam'!I:I,'master untuk shift 2'!E:E,'Shift Malam'!L:L) -> 0 | K89: NA-055
D90: 84 | E90: AES-006 FNS | F90: AES-006 | G90: =SUMIF('Shift Malam'!I:I,'master untuk shift 2'!E90,'Shift Malam'!L:L) -> 0 | H90: PRESS-B | I90: =SUMIF('Shift Malam'!I:I,'master untuk shift 2'!E:E,'Shift Malam'!L:L) -> 0 | K90: T214
D91: 85 | E91: AES-016 FNS | F91: AES-016 | G91: =SUMIF('Shift Malam'!I:I,'master untuk shift 2'!E91,'Shift Malam'!L:L) -> 0 | H91: PRESS-B | I91: =SUMIF('Shift Malam'!I:I,'master untuk shift 2'!E:E,'Shift Malam'!L:L) -> 0 | K91: NA-056
D92: 86 | E92: AES-017 FNS | F92: AES-017 | G92: =SUMIF('Shift Malam'!I:I,'master untuk shift 2'!E92,'Shift Malam'!L:L) -> 0 | H92: PRESS-B | I92: =SUMIF('Shift Malam'!I:I,'master untuk shift 2'!E:E,'Shift Malam'!L:L) -> 0 | K92: T214
D93: 87 | E93: IB-050 | F93: IB-050 | G93: =SUMIF('Shift Malam'!I:I,'master untuk shift 2'!E93,'Shift Malam'!L:L) -> 0 | H93: PRESS-Ds | I93: =SUMIF('Shift Malam'!I:I,'master untuk shift 2'!E:E,'Shift Malam'!L:L) -> 0
D94: 88 | E94: IB-077 | F94: IB-077 | G94: =SUMIF('Shift Malam'!I:I,'master untuk shift 2'!E94,'Shift Malam'!L:L) -> 0 | H94: PRESS-Ds | I94: =SUMIF('Shift Malam'!I:I,'master untuk shift 2'!E:E,'Shift Malam'!L:L) -> 0
D95: 89 | E95: G-013- | F95: G-014 | G95: =SUMIF('Shift Malam'!I:I,'master untuk shift 2'!E95,'Shift Malam'!L:L) -> 0 | H95: PRESS-Bs | I95: =SUMIF('Shift Malam'!I:I,'master untuk shift 2'!E:E,'Shift Malam'!L:L) -> 0
D96: 90 | E96: G-015- | F96: G-016 | G96: =SUMIF('Shift Malam'!I:I,'master untuk shift 2'!E96,'Shift Malam'!L:L) -> 0 | H96: PRESS-Bs | I96: =SUMIF('Shift Malam'!I:I,'master untuk shift 2'!E:E,'Shift Malam'!L:L) -> 0
D97: 91 | E97: G-013- | F97: G-013 | G97: =SUMIF('Shift Malam'!I:I,'master untuk shift 2'!E97,'Shift Malam'!L:L) -> 0 | H97: PRESS-Bs | I97: =SUMIF('Shift Malam'!I:I,'master untuk shift 2'!E:E,'Shift Malam'!L:L) -> 0
D98: 92 | E98: G-015- | F98: G-015 | G98: =SUMIF('Shift Malam'!I:I,'master untuk shift 2'!E98,'Shift Malam'!L:L) -> 0 | H98: PRESS-Bs | I98: =SUMIF('Shift Malam'!I:I,'master untuk shift 2'!E:E,'Shift Malam'!L:L) -> 0
D99: 93 | E99: G-013 | F99: G-014 | G99: =SUMIF('Shift Malam'!I:I,'master untuk shift 2'!E99,'Shift Malam'!L:L) -> 0 | H99: PRESS-Bs | I99: =SUMIF('Shift Malam'!I:I,'master untuk shift 2'!E:E,'Shift Malam'!L:L) -> 0
D100: 94 | E100: G-015 | F100: G-016 | G100: =SUMIF('Shift Malam'!I:I,'master untuk shift 2'!E100,'Shift Malam'!L:L) -> 0 | H100: PRESS-Bs | I100: =SUMIF('Shift Malam'!I:I,'master untuk shift 2'!E:E,'Shift Malam'!L:L) -> 0
D101: 95 | E101: G-013 | F101: G-013 | G101: =SUMIF('Shift Malam'!I:I,'master untuk shift 2'!E101,'Shift Malam'!L:L) -> 0 | H101: PRESS-Bs | I101: =SUMIF('Shift Malam'!I:I,'master untuk shift 2'!E:E,'Shift Malam'!L:L) -> 0
D102: 96 | E102: G-015 | F102: G-015 | G102: =SUMIF('Shift Malam'!I:I,'master untuk shift 2'!E102,'Shift Malam'!L:L) -> 0 | H102: PRESS-Bs | I102: =SUMIF('Shift Malam'!I:I,'master untuk shift 2'!E:E,'Shift Malam'!L:L) -> 0
D103: 97 | E103: G-028 | F103: G-028 | G103: =SUMIF('Shift Malam'!I:I,'master untuk shift 2'!E103,'Shift Malam'!L:L) -> 0 | H103: PRESS-Bs | I103: =SUMIF('Shift Malam'!I:I,'master untuk shift 2'!E:E,'Shift Malam'!L:L) -> 0
D104: 98 | E104: G-029 | F104: G-029 | G104: =SUMIF('Shift Malam'!I:I,'master untuk shift 2'!E104,'Shift Malam'!L:L) -> 0 | H104: PRESS-Bs | I104: =SUMIF('Shift Malam'!I:I,'master untuk shift 2'!E:E,'Shift Malam'!L:L) -> 0
... D202: 196 | E202: AES-029 FNS | F202: AES-029 | G202: =SUMIF('Shift Malam'!I:I,'master untuk shift 2'!E202,'Shift Malam'!L:L) -> 0 | H202: PRESS-B | I202: =SUMIF('Shift Malam'!I:I,'master untuk shift 2'!E:E,'Shift Malam'!L:L) -> 0
D203: 197 | E203: AES-029 FNS | F203: AES-034 | G203: =SUMIF('Shift Malam'!I:I,'master untuk shift 2'!E203,'Shift Malam'!L:L) -> 0 | H203: PRESS-B | I203: =SUMIF('Shift Malam'!I:I,'master untuk shift 2'!E:E,'Shift Malam'!L:L) -> 0 | J203: 100
D204: 198 | E204: AES-028 FNS | F204: AES-033 | G204: =SUMIF('Shift Malam'!I:I,'master untuk shift 2'!E204,'Shift Malam'!L:L) -> 0 | H204: PRESS-B | I204: =SUMIF('Shift Malam'!I:I,'master untuk shift 2'!E:E,'Shift Malam'!L:L) -> 0
...

Sheet Shift Pagi
AH2: FISM -PRO-01-03-01
E3: PPC SECTION
E4: PPLC DEPARTMENT
C5: PERMINTAAN HARIAN STAMPING
R7: QCC DAY KAMIS JAM 11;00 SAMPE JAM 11:45
R9: SPORT DAY RABU JAM 16:30 SAMPE JAM 18:00
R13: ISTIRAHAT SORE RAMADHAN
A15: =VLOOKUP($I15,MASTER!$B:$B,2,0) -> #N/A | C15: PRESS A | R15: ISTIRAHAT SORE | AA15: SHIFT | AB15: JAM | AD15: TOTAL
A16: =VLOOKUP($I16,MASTER!$B:$B,2,0) -> #N/A | R16: BREAKTIME | AB16: KERJA | AC16: MENIT | AD16: MENIT
A17: =VLOOKUP($I17,MASTER!$B:$B,2,0) -> #N/A | C17: Hari | D17: : Selasa Pagi | L17: DISTRIBUSI KE: | R17: ISTIRAHAT JUMAT | AA17: 1 | AB17: 8 | AC17: 60 | AD17: =+AB17*AC17 -> 480
A18: =VLOOKUP($I18,MASTER!$B:$B,2,0) -> #N/A | C18: Tgl | D18: : 05-Mei-2026 | L18: PROD | N18: IFP | P18: IRM | R18: CINGKORAK | W18: DS | AA18: OT | AC18: 60 | AD18: =+AB18*AC18 -> 0
A19: =VLOOKUP($I19,MASTER!$B:$B,2,0) -> #N/A | C19: Jam | D19: : 07:30 - 16:15 WIB | R19: ISTIRAHAT SIANG | AD19: 460
A20: =VLOOKUP($I20,MASTER!$B:$B,2,0) -> #N/A | C20: NO. | D20: JOB MASTER | E20: TYPE PLT | F20: QTY/ PLT | G20: KEB. MTL | H20: TOTAL PLT | I20: JOB NO. | K20: EACH PART | L20: PLAN | M20: OK | N20: REPAIR | O20: REJECT | P20: TOTAL MESIN | Q20: CT (") | R20: PROCESS TIME | S20: REG. ACTIVE | T20: DCT | U20: MCT | W20: PLAN DCT | X20: TPT | Y20: GSPH/ ITEM | Z20: START | AA20: FINISH | AB20: ACT START | AC20: ACT FINISH | AD20: KETERANGAN | AE20: A-1 | AF20: A-2 | AG20: A-3 | AH20: A-4 | AI20: DT (MENIT) | AJ20: TOTAL DT (MENIT) | AL20: JOB NO | AM20: IN | AN20: TPT | AR20: 0.31597222
A21: =VLOOKUP($I21,MASTER!$B:$B,2,0) -> #N/A | AR21: 0.69791664
A22: =VLOOKUP($I22,MASTER!$B:$B,2,0) -> #N/A | D22: =IF($I22="","",VLOOKUP($I22,MASTER!$G:$CF,2,0)) -> GT-6196 | E22: =IF($I22="","",VLOOKUP($I22,MASTER!$G:$CF,25,0)) -> R | F22: =IF($I22="","",VLOOKUP($I22,MASTER!$G:$CF,27,0)) -> 50 | G22: =+L22 -> 300 | H22: =IF($L22<$F22="0","0",IF($L22="","",ROUNDUP(L22/F22,1))) -> 6 | I22: K1155 | L22: 300 | P22: =IF($I22="","",VLOOKUP($I22,MASTER!$G:$CF,65,0)) -> 4 | Q22: 8 | R22: =IF(L22="","",+Q22*L22/60) -> 40 | T22: =IF($I22="","",VLOOKUP($I22,MASTER!$G:$CF,38,0)) -> 8 | V22: =IF(I22="","",SUM(R22:T22)) -> 48 | W22: =IF(I22="","",(S22+T22)*P22) -> 32 | X22: =IF(V22="","",ROUNDUP(V22,0)) -> 48 | Y22: =+L22/X22*60 -> 375 | Z22: 0.31944444 | AA22: =IF(I22="","",Z22+X22/1440) -> 0.35277778 | AE22: =IFERROR(IF($I22="","",VLOOKUP($I22,MASTER!$G:$CF,48,0))*$X22,0) -> 48 | AF22: =IFERROR(IF($I22="","",VLOOKUP($I22,MASTER!$G:$CF,49,0))*$X22,0) -> 48 | AG22: =IFERROR(IF($I22="","",VLOOKUP($I22,MASTER!$G:$CF,50,0))*$X22,0) -> 48 | AH22: =IFERROR(IF($I22="","",VLOOKUP($I22,MASTER!$G:$CF,51,0))*$X22,0) -> 48 | AK22: =IF(L22="",0,P22*L22) -> 1200 | AL22: =I22 -> K1155 | AM22: =Z22 -> 0.31944444 | AN22: =IF(L22="","",L22*P22) -> 1200 | AO22: =IF(X22="","",X22*P22) -> 192 | AP22: =+X22/(60*24) -> 0.033333333
A23: =VLOOKUP($I23,MASTER!$B:$B,2,0) -> #N/A | D23: =IF($I23="","",VLOOKUP($I23,MASTER!$G:$CF,2,0)) -> GT-6197 GAL | E23: =IF($I23="","",VLOOKUP($I23,MASTER!$G:$CF,25,0)) -> R | F23: =IF($I23="","",VLOOKUP($I23,MASTER!$G:$CF,27,0)) -> 50 | G23: =+L23 -> 250 | H23: =IF($L23<$F23="0","0",IF($L23="","",ROUNDUP(L23/F23,1))) -> 5 | I23: K1157 | L23: 250 | P23: =IF($I23="","",VLOOKUP($I23,MASTER!$G:$CF,65,0)) -> 4 | Q23: 8 | R23: =IF(L23="","",+Q23*L23/60) -> 33.333333 | T23: =IF($I23="","",VLOOKUP($I23,MASTER!$G:$CF,38,0)) -> 8 | V23: =IF(I23="","",SUM(R23:T23)) -> 41.333333 | W23: =IF(I23="","",(S23+T23)*P23) -> 32 | X23: =IF(V23="","",ROUNDUP(V23,0)) -> 42 | Y23: =+L23/X23*60 -> 357.14286 | Z23: =+AA22 -> 0.35277778 | AA23: =IF(I23="","",Z23+X23/1440) -> 0.38194444 | AE23: =IFERROR(IF($I23="","",VLOOKUP($I23,MASTER!$G:$CF,48,0))*$X23,0) -> 42 | AF23: =IFERROR(IF($I23="","",VLOOKUP($I23,MASTER!$G:$CF,49,0))*$X23,0) -> 42 | AG23: =IFERROR(IF($I23="","",VLOOKUP($I23,MASTER!$G:$CF,50,0))*$X23,0) -> 42 | AH23: =IFERROR(IF($I23="","",VLOOKUP($I23,MASTER!$G:$CF,51,0))*$X23,0) -> 42 | AK23: =IF(L23="",0,P23*L23) -> 1000 | AL23: =I23 -> K1157 | AM23: =Z23 -> 0.35277778 | AN23: =IF(L23="","",L23*P23) -> 1000 | AO23: =IF(X23="","",X23*P23) -> 168 | AP23: =+X23/(60*24) -> 0.029166667
A24: =VLOOKUP($I24,MASTER!$B:$B,2,0) -> #N/A | D24: =IF($I24="","",VLOOKUP($I24,MASTER!$G:$CF,2,0)) -> AES-023 | E24: =IF($I24="","",VLOOKUP($I24,MASTER!$G:$CF,25,0)) -> KHS | F24: =IF($I24="","",VLOOKUP($I24,MASTER!$G:$CF,27,0)) -> 240 | G24: =+L24 -> 480 | H24: =IF($L24<$F24="0","0",IF($L24="","",ROUNDUP(L24/F24,1))) -> 2 | I24: AES-023 WIP | L24: 480 | N24: =+L24 -> 480 | P24: =IF($I24="","",VLOOKUP($I24,MASTER!$G:$CF,65,0)) -> 4 | Q24: 6.5 | R24: =IF(L24="","",+Q24*L24/60) -> 52 | T24: =IF($I24="","",VLOOKUP($I24,MASTER!$G:$CF,38,0)) -> 7 | V24: =IF(I24="","",SUM(R24:T24)) -> 59 | W24: =IF(I24="","",(S24+T24)*P24) -> 28 | X24: =IF(V24="","",ROUNDUP(V24,0)) -> 59 | Y24: =+L24/X24*60 -> 488.13559 | Z24: =+AA23 -> 0.38194444 | AA24: =IF(I24="","",Z24+X24/1440) -> 0.42291667 | AE24: =IFERROR(IF($I24="","",VLOOKUP($I24,MASTER!$G:$CF,48,0))*$X24,0) -> 59 | AF24: =IFERROR(IF($I24="","",VLOOKUP($I24,MASTER!$G:$CF,49,0))*$X24,0) -> 59 | AG24: =IFERROR(IF($I24="","",VLOOKUP($I24,MASTER!$G:$CF,50,0))*$X24,0) -> 59 | AH24: =IFERROR(IF($I24="","",VLOOKUP($I24,MASTER!$G:$CF,51,0))*$X24,0) -> 59 | AK24: =IF(L24="",0,P24*L24) -> 1920 | AL24: =I24 -> AES-023 WIP | AM24: =Z24 -> 0.38194444 | AN24: =IF(L24="","",L24*P24) -> 1920 | AO24: =IF(X24="","",X24*P24) -> 236 | AP24: =+X24/(60*24) -> 0.040972222
A25: =VLOOKUP($I25,MASTER!$B:$B,2,0) -> #N/A | D25: =IF($I25="","",VLOOKUP($I25,MASTER!$G:$CF,2,0)) -> AES-028 WIP | E25: =IF($I25="","",VLOOKUP($I25,MASTER!$G:$CF,25,0)) -> D | F25: =IF($I25="","",VLOOKUP($I25,MASTER!$G:$CF,27,0)) -> 240 | G25: =+L25 -> 480 | H25: =IF($L25<$F25="0","0",IF($L25="","",ROUNDUP(L25/F25,1))) -> 2 | I25: AES-028 WIP | L25: 480 | N25: =+L25 -> 480 | P25: =IF($I25="","",VLOOKUP($I25,MASTER!$G:$CF,65,0)) -> 4 | Q25: 6.5 | R25: =IF(L25="","",+Q25*L25/60) -> 52 | T25: =IF($I25="","",VLOOKUP($I25,MASTER!$G:$CF,38,0)) -> 7 | V25: =IF(I25="","",SUM(R25:T25)) -> 59 | W25: =IF(I25="","",(S25+T25)*P25) -> 28 | X25: =IF(V25="","",ROUNDUP(V25,0)) -> 59 | Y25: =+L25/X25*60 -> 488.13559 | Z25: =+AA24 -> 0.42291667 | AA25: =IF(I25="","",Z25+X25/1440) -> 0.46388889 | AE25: =IFERROR(IF($I25="","",VLOOKUP($I25,MASTER!$G:$CF,48,0))*$X25,0) -> 59 | AF25: =IFERROR(IF($I25="","",VLOOKUP($I25,MASTER!$G:$CF,49,0))*$X25,0) -> 59 | AG25: =IFERROR(IF($I25="","",VLOOKUP($I25,MASTER!$G:$CF,50,0))*$X25,0) -> 59 | AH25: =IFERROR(IF($I25="","",VLOOKUP($I25,MASTER!$G:$CF,51,0))*$X25,0) -> 59 | AK25: =IF(L25="",0,P25*L25) -> 1920 | AL25: =I25 -> AES-028 WIP | AM25: =Z25 -> 0.42291667 | AN25: =IF(L25="","",L25*P25) -> 1920 | AO25: =IF(X25="","",X25*P25) -> 236 | AP25: =+X25/(60*24) -> 0.040972222
A26: =VLOOKUP($I26,MASTER!$B:$B,2,0) -> #N/A | D26: =IF($I26="","",VLOOKUP($I26,MASTER!$G:$CF,2,0)) -> AES-024 | E26: =IF($I26="","",VLOOKUP($I26,MASTER!$G:$CF,25,0)) -> KHS | F26: =IF($I26="","",VLOOKUP($I26,MASTER!$G:$CF,27,0)) -> 240 | G26: =+L26 -> 410 | H26: =IF($L26<$F26="0","0",IF($L26="","",ROUNDUP(L26/F26,1))) -> 1.8 | I26: AES-024 WIP | L26: 410 | P26: =IF($I26="","",VLOOKUP($I26,MASTER!$G:$CF,65,0)) -> 4 | Q26: 6.5 | R26: =IF(L26="","",+Q26*L26/60) -> 44.416667 | T26: =IF($I26="","",VLOOKUP($I26,MASTER!$G:$CF,38,0)) -> 7 | V26: =IF(I26="","",SUM(R26:T26)) -> 51.416667 | W26: =IF(I26="","",(S26+T26)*P26) -> 28 | X26: =IF(V26="","",ROUNDUP(V26,0)) -> 52 | Y26: =+L26/X26*60 -> 473.07692 | Z26: =+AA25 -> 0.46388889 | AA26: =IF(I26="","",Z26+X26/1440) -> 0.5 | AE26: =IFERROR(IF($I26="","",VLOOKUP($I26,MASTER!$G:$CF,48,0))*$X26,0) -> 52 | AF26: =IFERROR(IF($I26="","",VLOOKUP($I26,MASTER!$G:$CF,49,0))*$X26,0) -> 52 | AG26: =IFERROR(IF($I26="","",VLOOKUP($I26,MASTER!$G:$CF,50,0))*$X26,0) -> 52 | AH26: =IFERROR(IF($I26="","",VLOOKUP($I26,MASTER!$G:$CF,51,0))*$X26,0) -> 52 | AK26: =IF(L26="",0,P26*L26) -> 1640 | AL26: =I26 -> AES-024 WIP | AM26: =Z26 -> 0.46388889 | AN26: =IF(L26="","",L26*P26) -> 1640 | AO26: =IF(X26="","",X26*P26) -> 208 | AP26: =+X26/(60*24) -> 0.036111111
A27: =VLOOKUP($I27,MASTER!$B:$B,2,0) -> #N/A | D27: =IF($I27="","",VLOOKUP($I27,MASTER!$G:$CF,2,0)) -> 0 | E27: =IF($I27="","",VLOOKUP($I27,MASTER!$G:$CF,25,0)) -> 0 | F27: =IF($I27="","",VLOOKUP($I27,MASTER!$G:$CF,27,0)) -> 0 | G27: =+L27 -> 0 | H27: =IF($L27<$F27="0","0",IF($L27="","",ROUNDUP(L27/F27,1))) | I27: ISTIRAHAT SIANG | N27: =+L27 -> 0 | P27: =IF($I27="","",VLOOKUP($I27,MASTER!$G:$CF,65,0)) -> 0 | R27: =IF(L27="","",+Q27*L27/60) | T27: =IF($I27="","",VLOOKUP($I27,MASTER!$G:$CF,38,0)) -> 40 | V27: =IF(I27="","",SUM(R27:T27)) -> 40 | W27: =IF(I27="","",(S27+T27)*P27) -> 0 | X27: =IF(V27="","",ROUNDUP(V27,0)) -> 40 | Y27: =+L27/X27*60 -> 0 | Z27: =+AA26 -> 0.5 | AA27: =IF(I27="","",Z27+X27/1440) -> 0.52777778 | AE27: =IFERROR(IF($I27="","",VLOOKUP($I27,MASTER!$G:$CF,48,0))*$X27,0) -> 0 | AF27: =IFERROR(IF($I27="","",VLOOKUP($I27,MASTER!$G:$CF,49,0))*$X27,0) -> 0 | AG27: =IFERROR(IF($I27="","",VLOOKUP($I27,MASTER!$G:$CF,50,0))*$X27,0) -> 0 | AH27: =IFERROR(IF($I27="","",VLOOKUP($I27,MASTER!$G:$CF,51,0))*$X27,0) -> 0 | AK27: =IF(L27="",0,P27*L27) -> 0 | AL27: =I27 -> ISTIRAHAT SIANG | AM27: =Z27 -> 0.5 | AN27: =IF(L27="","",L27*P27) | AO27: =IF(X27="","",X27*P27) -> 0 | AP27: =+X27/(60*24) -> 0.027777778
A28: =VLOOKUP($I28,MASTER!$B:$B,2,0) -> #N/A | D28: =IF($I28="","",VLOOKUP($I28,MASTER!$G:$CF,2,0)) -> AES-024 | E28: =IF($I28="","",VLOOKUP($I28,MASTER!$G:$CF,25,0)) -> KHS | F28: =IF($I28="","",VLOOKUP($I28,MASTER!$G:$CF,27,0)) -> 240 | G28: =+L28 -> 70 | H28: =IF($L28<$F28="0","0",IF($L28="","",ROUNDUP(L28/F28,1))) -> 0.3 | I28: AES-024 WIP | L28: =480-L26 -> 70 | P28: =IF($I28="","",VLOOKUP($I28,MASTER!$G:$CF,65,0)) -> 4 | Q28: 6.5 | R28: =IF(L28="","",+Q28*L28/60) -> 7.5833333 | V28: =IF(I28="","",SUM(R28:T28)) -> 7.5833333 | W28: =IF(I28="","",(S28+T28)*P28) -> 0 | X28: =IF(V28="","",ROUNDUP(V28,0))-1 -> 7 | Y28: =+L28/X28*60 -> 600 | Z28: =+AA27 -> 0.52777778 | AA28: =IF(I28="","",Z28+X28/1440) -> 0.53263889 | AE28: =IFERROR(IF($I28="","",VLOOKUP($I28,MASTER!$G:$CF,48,0))*$X28,0) -> 7 | AF28: =IFERROR(IF($I28="","",VLOOKUP($I28,MASTER!$G:$CF,49,0))*$X28,0) -> 7 | AG28: =IFERROR(IF($I28="","",VLOOKUP($I28,MASTER!$G:$CF,50,0))*$X28,0) -> 7 | AH28: =IFERROR(IF($I28="","",VLOOKUP($I28,MASTER!$G:$CF,51,0))*$X28,0) -> 7 | AK28: =IF(L28="",0,P28*L28) -> 280 | AL28: =I28 -> AES-024 WIP | AM28: =Z28 -> 0.52777778 | AN28: =IF(L28="","",L28*P28) -> 280 | AO28: =IF(X28="","",X28*P28) -> 28 | AP28: =+X28/(60*24) -> 0.0048611111
A29: =VLOOKUP($I29,MASTER!$B:$B,2,0) -> #N/A | D29: =IF($I29="","",VLOOKUP($I29,MASTER!$G:$CF,2,0)) -> IB-094/5 Shoulder 700P | E29: =IF($I29="","",VLOOKUP($I29,MASTER!$G:$CF,25,0)) -> E | F29: =IF($I29="","",VLOOKUP($I29,MASTER!$G:$CF,27,0)) -> 90 | G29: =+L29 -> 240 | H29: =IF($L29<$F29="0","0",IF($L29="","",ROUNDUP(L29/F29,1))) -> 2.7 | I29: IB-094 WIP | L29: 240 | P29: =IF($I29="","",VLOOKUP($I29,MASTER!$G:$CF,65,0)) -> 1 | Q29: =IF($I29="","",VLOOKUP($I29,MASTER!$G:$CF,37,0)) -> 8 | R29: =IF(L29="","",+Q29*L29/60) -> 32 | T29: =IF($I29="","",VLOOKUP($I29,MASTER!$G:$CF,38,0)) -> 5 | V29: =IF(I29="","",SUM(R29:T29)) -> 37 | W29: =IF(I29="","",(S29+T29)*P29) -> 5 | X29: =IF(V29="","",ROUNDUP(V29,0)) -> 37 | Y29: =+L29/X29*60 -> 389.18919 | Z29: =+AA28 -> 0.53263889 | AA29: =IF(I29="","",Z29+X29/1440) -> 0.55833333 | AE29: =IFERROR(IF($I29="","",VLOOKUP($I29,MASTER!$G:$CF,48,0))*$X29,0) -> 37 | AF29: =IFERROR(IF($I29="","",VLOOKUP($I29,MASTER!$G:$CF,49,0))*$X29,0) -> 37 | AG29: =IFERROR(IF($I29="","",VLOOKUP($I29,MASTER!$G:$CF,50,0))*$X29,0) -> 37 | AH29: =IFERROR(IF($I29="","",VLOOKUP($I29,MASTER!$G:$CF,51,0))*$X29,0) -> 37 | AK29: =IF(L29="",0,P29*L29) -> 240 | AL29: =I29 -> IB-094 WIP | AM29: =Z29 -> 0.53263889 | AN29: =IF(L29="","",L29*P29) -> 240 | AO29: =IF(X29="","",X29*P29) -> 37 | AP29: =+X29/(60*24) -> 0.025694444
A30: =VLOOKUP($I30,MASTER!$B:$B,2,0) -> #N/A | D30: =IF($I30="","",VLOOKUP($I30,MASTER!$G:$CF,2,0)) -> IB-099/100 Gusset 700P | E30: =IF($I30="","",VLOOKUP($I30,MASTER!$G:$CF,25,0)) -> E | F30: =IF($I30="","",VLOOKUP($I30,MASTER!$G:$CF,27,0)) -> 90 | G30: =+L30 -> 240 | H30: =IF($L30<$F30="0","0",IF($L30="","",ROUNDUP(L30/F30,1))) -> 2.7 | I30: IB-098 WIP | L30: 240 | P30: =IF($I30="","",VLOOKUP($I30,MASTER!$G:$CF,65,0)) -> 1 | Q30: =IF($I30="","",VLOOKUP($I30,MASTER!$G:$CF,37,0)) -> 8 | R30: =IF(L30="","",+Q30*L30/60) -> 32 | T30: =IF($I30="","",VLOOKUP($I30,MASTER!$G:$CF,38,0)) -> 5 | V30: =IF(I30="","",SUM(R30:T30)) -> 37 | W30: =IF(I30="","",(S30+T30)*P30) -> 5 | X30: =IF(V30="","",ROUNDUP(V30,0)) -> 37 | Y30: =+L30/X30*60 -> 389.18919 | Z30: =+AA29 -> 0.55833333 | AA30: =IF(I30="","",Z30+X30/1440) -> 0.58402778 | AE30: =IFERROR(IF($I30="","",VLOOKUP($I30,MASTER!$G:$CF,48,0))*$X30,0) -> 37 | AF30: =IFERROR(IF($I30="","",VLOOKUP($I30,MASTER!$G:$CF,49,0))*$X30,0) -> 37 | AG30: =IFERROR(IF($I30="","",VLOOKUP($I30,MASTER!$G:$CF,50,0))*$X30,0) -> 37 | AH30: =IFERROR(IF($I30="","",VLOOKUP($I30,MASTER!$G:$CF,51,0))*$X30,0) -> 37 | AK30: =IF(L30="",0,P30*L30) -> 240 | AL30: =I30 -> IB-098 WIP | AM30: =Z30 -> 0.55833333 | AN30: =IF(L30="","",L30*P30) -> 240 | AO30: =IF(X30="","",X30*P30) -> 37 | AP30: =+X30/(60*24) -> 0.025694444
A31: =VLOOKUP($I31,MASTER!$B:$B,2,0) -> #REF! | D31: =IF($I31="","",VLOOKUP($I31,MASTER!$G:$CF,2,0)) -> IB-023/24 | E31: =IF($I31="","",VLOOKUP($I31,MASTER!$G:$CF,25,0)) -> C2 | F31: =IF($I31="","",VLOOKUP($I31,MASTER!$G:$CF,27,0)) -> 240 | G31: =+L31 -> 60 | H31: =IF($L31<$F31="0","0",IF($L31="","",ROUNDUP(L31/F31,1))) -> 0.3 | I31: IB-023 | L31: 60 | P31: =IF($I31="","",VLOOKUP($I31,MASTER!$G:$CF,65,0)) -> 4 | Q31: 6.5 | R31: =IF(L31="","",+Q31*L31/60) -> 6.5 | S31: 45 | T31: =IF($I31="","",VLOOKUP($I31,MASTER!$G:$CF,38,0)) -> 5 | V31: =IF(I31="","",SUM(R31:T31)) -> 56.5 | W31: =IF(I31="","",(S31+T31)*P31) -> 200 | X31: =IF(V31="","",ROUNDUP(V31,0)) -> 57 | Y31: =+L31/X31*60 -> 63.157895 | Z31: =+AA30 -> 0.58402778 | AA31: =IF(I31="","",Z31+X31/1440) -> 0.62361111 | AD31: 45" Trial | AE31: =IFERROR(IF($I31="","",VLOOKUP($I31,MASTER!$G:$CF,48,0))*$X31,0) -> 57 | AF31: =IFERROR(IF($I31="","",VLOOKUP($I31,MASTER!$G:$CF,49,0))*$X31,0) -> 57 | AG31: =IFERROR(IF($I31="","",VLOOKUP($I31,MASTER!$G:$CF,50,0))*$X31,0) -> 57 | AH31: =IFERROR(IF($I31="","",VLOOKUP($I31,MASTER!$G:$CF,51,0))*$X31,0) -> 57 | AK31: =IF(L31="",0,P31*L31) -> 240 | AL31: =I31 -> IB-023 | AM31: =Z31 -> 0.58402778 | AN31: =IF(L31="","",L31*P31) -> 240 | AO31: =IF(X31="","",X31*P31) -> 228 | AP31: =+X31/(60*24) -> 0.039583333
A32: =VLOOKUP($I32,MASTER!$B:$B,2,0) -> #N/A | D32: =IF($I32="","",VLOOKUP($I32,MASTER!$G:$CF,2,0)) -> GT-5154 BLK/ K-1056 | E32: =IF($I32="","",VLOOKUP($I32,MASTER!$G:$CF,25,0)) -> BESI | F32: =IF($I32="","",VLOOKUP($I32,MASTER!$G:$CF,27,0)) -> 250 | G32: =+L32 -> 50 | H32: =IF($L32<$F32="0","0",IF($L32="","",ROUNDUP(L32/F32,1))) -> 0.2 | I32: GT-5154 BLK DRAW1 | L32: 50 | P32: =IF($I32="","",VLOOKUP($I32,MASTER!$G:$CF,65,0)) -> 1 | Q32: =IF($I32="","",VLOOKUP($I32,MASTER!$G:$CF,37,0)) -> 8 | R32: =IF(L32="","",+Q32*L32/60) -> 6.6666667 | T32: =IF($I32="","",VLOOKUP($I32,MASTER!$G:$CF,38,0)) -> 10 | V32: =IF(I32="","",SUM(R32:T32)) -> 16.666667 | W32: =IF(I32="","",(S32+T32)*P32) -> 10 | X32: =IF(V32="","",ROUNDUP(V32,0)) -> 17 | Y32: =+L32/X32*60 -> 176.47059 | Z32: =+AA31 -> 0.62361111 | AA32: =IF(I32="","",Z32+X32/1440) -> 0.63541667 | AE32: =IFERROR(IF($I32="","",VLOOKUP($I32,MASTER!$G:$CF,48,0))*$X32,0) -> 17 | AF32: =IFERROR(IF($I32="","",VLOOKUP($I32,MASTER!$G:$CF,49,0))*$X32,0) -> 0 | AG32: =IFERROR(IF($I32="","",VLOOKUP($I32,MASTER!$G:$CF,50,0))*$X32,0) -> 0 | AH32: =IFERROR(IF($I32="","",VLOOKUP($I32,MASTER!$G:$CF,51,0))*$X32,0) -> 17 | AK32: =IF(L32="",0,P32*L32) -> 50 | AL32: =I32 -> GT-5154 BLK DRAW1 | AM32: =Z32 -> 0.62361111 | AN32: =IF(L32="","",L32*P32) -> 50 | AO32: =IF(X32="","",X32*P32) -> 17 | AP32: =+X32/(60*24) -> 0.011805556
A33: =VLOOKUP($I33,MASTER!$B:$B,2,0) -> #N/A | D33: =IF($I33="","",VLOOKUP($I33,MASTER!$G:$CF,2,0)) -> 0 | E33: =IF($I33="","",VLOOKUP($I33,MASTER!$G:$CF,25,0)) -> 0 | F33: =IF($I33="","",VLOOKUP($I33,MASTER!$G:$CF,27,0)) -> 0 | G33: =+L33 -> 0 | H33: =IF($L33<$F33="0","0",IF($L33="","",ROUNDUP(L33/F33,1))) | I33: CINGKORAK | P33: =IF($I33="","",VLOOKUP($I33,MASTER!$G:$CF,65,0)) -> 0 | R33: =IF(L33="","",+Q33*L33/60) | T33: =IF($I33="","",VLOOKUP($I33,MASTER!$G:$CF,38,0)) -> 15 | V33: =IF(I33="","",SUM(R33:T33)) -> 15 | W33: =IF(I33="","",(S33+T33)*P33) -> 0 | X33: =IF(V33="","",ROUNDUP(V33,0)) -> 15 | Y33: =+L33/X33*60 -> 0 | Z33: =+AA32 -> 0.63541667 | AA33: =IF(I33="","",Z33+X33/1440) -> 0.64583333 | AE33: =IFERROR(IF($I33="","",VLOOKUP($I33,MASTER!$G:$CF,48,0))*$X33,0) -> 0 | AF33: =IFERROR(IF($I33="","",VLOOKUP($I33,MASTER!$G:$CF,49,0))*$X33,0) -> 0 | AG33: =IFERROR(IF($I33="","",VLOOKUP($I33,MASTER!$G:$CF,50,0))*$X33,0) -> 0 | AH33: =IFERROR(IF($I33="","",VLOOKUP($I33,MASTER!$G:$CF,51,0))*$X33,0) -> 0 | AK33: =IF(L33="",0,P33*L33) -> 0 | AL33: =I33 -> CINGKORAK | AM33: =Z33 -> 0.63541667 | AN33: =IF(L33="","",L33*P33) | AO33: =IF(X33="","",X33*P33) -> 0 | AP33: =+X33/(60*24) -> 0.010416667
A34: =VLOOKUP($I34,MASTER!$B:$B,2,0) -> #N/A | D34: =IF($I34="","",VLOOKUP($I34,MASTER!$G:$CF,2,0)) -> GT-5154 BLK/ K-1056 | E34: =IF($I34="","",VLOOKUP($I34,MASTER!$G:$CF,25,0)) -> BESI | F34: =IF($I34="","",VLOOKUP($I34,MASTER!$G:$CF,27,0)) -> 250 | G34: =+L34 -> 335 | H34: =IF($L34<$F34="0","0",IF($L34="","",ROUNDUP(L34/F34,1))) -> 1.4 | I34: GT-5154 BLK DRAW1 | L34: 335 | N34: =+L34 -> 335 | P34: =IF($I34="","",VLOOKUP($I34,MASTER!$G:$CF,65,0)) -> 1 | Q34: 8 | R34: =IF(L34="","",+Q34*L34/60) -> 44.666667 | V34: =IF(I34="","",SUM(R34:T34)) -> 44.666667 | W34: =IF(I34="","",(S34+T34)*P34) -> 0 | X34: =IF(V34="","",ROUNDUP(V34,0)) -> 45 | Y34: =+L34/X34*60 -> 446.66667 | Z34: =+AA33 -> 0.64583333 | AA34: =IF(I34="","",Z34+X34/1440) -> 0.67708333 | AE34: =IFERROR(IF($I34="","",VLOOKUP($I34,MASTER!$G:$CF,48,0))*$X34,0) -> 45 | AF34: =IFERROR(IF($I34="","",VLOOKUP($I34,MASTER!$G:$CF,49,0))*$X34,0) -> 0 | AG34: =IFERROR(IF($I34="","",VLOOKUP($I34,MASTER!$G:$CF,50,0))*$X34,0) -> 0 | AH34: =IFERROR(IF($I34="","",VLOOKUP($I34,MASTER!$G:$CF,51,0))*$X34,0) -> 45 | AK34: =IF(L34="",0,P34*L34) -> 335 | AL34: =I34 -> GT-5154 BLK DRAW1 | AM34: =Z34 -> 0.64583333 | AN34: =IF(L34="","",L34*P34) -> 335 | AO34: =IF(X34="","",X34*P34) -> 45 | AP34: =+X34/(60*24) -> 0.03125
