Workbook

Sheet GSPH REPAIR REJECT 2026
B2: ACHIEVEMENT REPORT OF ONE YEAR POLICY 2026
B3: PT INTI PANTJA PRESS INDUSTRI
B5: CONTROL ITEM | C5: DESCRIPTION | E5: TARGET KPI | F5: TARGET | G5: ACHIEVEMENT
G6: JAN | H6: FEB | I6: MAR | J6: APR | K6: MAY | L6: JUN | M6: JUL | N6: AUG | O6: SEP | P6: OCT | Q6: NOV | R6: DEC
B7: 1. Productivity | C7: 1. GSPH
C8: a. Press A | D8: Monthly | E8: 540 | F8: 537.35408 | G8: ='DETAIL 2026'!D7 -> 440.21871 | H8: ='DETAIL 2026'!E7 -> 449.13812 | I8: ='DETAIL 2026'!F7 -> 454.16948 | J8: ='DETAIL 2026'!G7 -> 458.80246 | K8: ='DETAIL 2026'!H7 -> 455.3847 | L8: ='DETAIL 2026'!I7 -> 457.14549 | M8: ='DETAIL 2026'!J7 -> 457.51863
C9: b. Press B | D9: Monthly | E9: 550 | F9: 565.84342 | G9: ='DETAIL 2026'!D15 -> 473.65622 | H9: ='DETAIL 2026'!E15 -> 455.1773 | I9: ='DETAIL 2026'!F15 -> 443.7973 | J9: ='DETAIL 2026'!G15 -> 414.33667 | K9: ='DETAIL 2026'!H15 -> 443.98243 | L9: ='DETAIL 2026'!I15 -> 440.40309 | M9: ='DETAIL 2026'!J15 -> 441.4709
C10: c. Press C | D10: Monthly | E10: 355 | F10: 255.52571 | G10: ='DETAIL 2026'!D23 -> 195.34378 | H10: ='DETAIL 2026'!E23 -> 214.69457 | I10: ='DETAIL 2026'!F23 -> 205.20642 | J10: ='DETAIL 2026'!G23 -> 214.00497 | K10: ='DETAIL 2026'!H23 -> 211.2541 | L10: ='DETAIL 2026'!I23 -> 201.35464 | M10: ='DETAIL 2026'!J23 -> 210.15226
C11: d. Press D | D11: Monthly | E11: 535 | F11: 537.63713 | G11: ='DETAIL 2026'!D31 -> 431.52986 | H11: ='DETAIL 2026'!E31 -> 445.07106 | I11: ='DETAIL 2026'!F31 -> 448.28354 | J11: ='DETAIL 2026'!G31 -> 429.66083 | K11: ='DETAIL 2026'!H31 -> 440.34578 | L11: ='DETAIL 2026'!I31 -> 427.59333 | M11: ='DETAIL 2026'!J31 -> 440.15541
C12: e. Press E | D12: Monthly | E12: 450 | F12: 351.70984 | G12: ='DETAIL 2026'!D39 -> 425.5091 | H12: ='DETAIL 2026'!E39 -> 406.6438 | I12: ='DETAIL 2026'!F39 -> 411.38722 | J12: ='DETAIL 2026'!G39 -> 410.2198 | K12: ='DETAIL 2026'!H39 -> 414.66228 | L12: ='DETAIL 2026'!I39 -> 435.54652 | M12: ='DETAIL 2026'!J39 -> 240
C13: f. Press F | D13: Monthly | E13: 550 | F13: 536.30442 | G13: ='DETAIL 2026'!D47 -> 513.165 | H13: ='DETAIL 2026'!E47 -> 505.14389 | I13: ='DETAIL 2026'!F47 -> 525.36892 | J13: ='DETAIL 2026'!G47 -> 522.0044 | K13: ='DETAIL 2026'!H47 -> 513.10876 | L13: ='DETAIL 2026'!I47 -> 523.63075 | M13: ='DETAIL 2026'!J47 -> 240
C14: g. Press K | D14: Monthly | E14: 550 | F14: 430.43227 | G14: ='DETAIL 2026'!D55 -> 612.56158 | H14: ='DETAIL 2026'!E55 -> 547.93795 | I14: ='DETAIL 2026'!F55 -> 541.41132 | J14: ='DETAIL 2026'!G55 -> 547.17153 | K14: ='DETAIL 2026'!H55 -> 551.05138 | L14: ='DETAIL 2026'!I55 -> 549.69238 | M14: ='DETAIL 2026'!J55 -> 240
C15: h. Press Line | D15: Monthly | E15: 500 | F15: 486.12852 | G15: ='DETAIL 2026'!D63 -> 476.31005 | H15: ='DETAIL 2026'!E63 -> 457.14462 | I15: ='DETAIL 2026'!F63 -> 452.19075 | J15: ='DETAIL 2026'!G63 -> 451.18406 | K15: ='DETAIL 2026'!H63 -> 461.10915 | L15: ='DETAIL 2026'!I63 -> 455.01033 | M15: ='DETAIL 2026'!J63 -> 381.9646
C16: i. Press Line | D16: Ytd | E16: 510 | G16: ='DETAIL 2026'!D68 -> 476.31005 | H16: ='DETAIL 2026'!E68 -> 466.51276 | I16: ='DETAIL 2026'!F68 -> 462.58643 | J16: ='DETAIL 2026'!G68 -> 459.39619 | K16: ='DETAIL 2026'!H68 -> 459.73638 | L16: ='DETAIL 2026'!I68 -> 458.94529 | M16: ='DETAIL 2026'!J68 -> 451.86144
C17: (avg GSPH = tot Stroke/TPT)
B19: 2. Quality | C19: 1. Repair Rate Press Line
C20: a. Repair Rate Press A | D20: Monthly | E20: 0.01 | G20: ='DETAIL 2026'!D84 -> 0.0021540698 | H20: ='DETAIL 2026'!E84 -> 0.00052051705 | I20: ='DETAIL 2026'!F84 -> 0.00022372418 | J20: ='DETAIL 2026'!G84 -> 0.00181909 | K20: ='DETAIL 2026'!H84 -> 0.00011330278 | L20: ='DETAIL 2026'!I84 -> 0.0027676974 | M20: ='DETAIL 2026'!J84 -> 0.0012470921
C21: b. Repair Rate Press B | D21: Monthly | E21: 0.01 | G21: ='DETAIL 2026'!D105 -> 0.0059926049 | H21: ='DETAIL 2026'!E105 -> 0.017598564 | I21: ='DETAIL 2026'!F105 -> 0.014827985 | J21: ='DETAIL 2026'!G105 -> 0.0066699599 | K21: ='DETAIL 2026'!H105 -> 0.0008140237 | L21: ='DETAIL 2026'!I105 -> 0.01418732 | M21: ='DETAIL 2026'!J105 -> 0.0092252659
C22: c. Repair Rate Press C | D22: Monthly | E22: 0.01 | G22: ='DETAIL 2026'!D126 -> 0.037548035 | H22: ='DETAIL 2026'!E126 -> 0.035991074 | I22: ='DETAIL 2026'!F126 -> 0.032952929 | J22: ='DETAIL 2026'!G126 -> 0.038486486 | K22: ='DETAIL 2026'!H126 -> 0.030477098 | L22: ='DETAIL 2026'!I126 -> 0.040752713 | M22: ='DETAIL 2026'!J126 -> 0.037100054
C23: d. Repair Rate Press D | D23: Monthly | E23: 0.01 | G23: ='DETAIL 2026'!D147 -> 0.012898857 | H23: ='DETAIL 2026'!E147 -> 0.018018557 | I23: ='DETAIL 2026'!F147 -> 0.015369595 | J23: ='DETAIL 2026'!G147 -> 0.0029494299 | K23: ='DETAIL 2026'!H147 -> 0.0056271278 | L23: ='DETAIL 2026'!I147 -> 0.0056098924 | M23: ='DETAIL 2026'!J147 -> 0.010168842
C24: e. Repair Rate Press E | D24: Monthly | E24: 0.01 | G24: ='DETAIL 2026'!D168 -> 0.015388253 | H24: ='DETAIL 2026'!E168 -> 0.019259048 | I24: ='DETAIL 2026'!F168 -> 0.015421674 | J24: ='DETAIL 2026'!G168 -> 0.023448769 | K24: ='DETAIL 2026'!H168 -> 0.030494238 | L24: ='DETAIL 2026'!I168 -> 0.023227833 | M24: ='DETAIL 2026'!J168 -> 0.01855114
C25: f. Repair Rate Press F | D25: Monthly | E25: 0.01 | G25: ='DETAIL 2026'!D189 -> 0.001774834 | H25: ='DETAIL 2026'!E189 -> 0.0021076826 | I25: ='DETAIL 2026'!F189 -> 0.0022859954 | J25: ='DETAIL 2026'!G189 -> 0.0061378168 | K25: ='DETAIL 2026'!H189 -> 0.0037757298 | L25: ='DETAIL 2026'!I189 -> 0.0055571138 | M25: ='DETAIL 2026'!J189 -> 0.0092221848
C26: g. Repair Rate Press K | D26: Monthly | E26: 0.01 | G26: ='DETAIL 2026'!D210 -> 0 | H26: ='DETAIL 2026'!E210 -> 0 | I26: ='DETAIL 2026'!F210 -> 0 | J26: ='DETAIL 2026'!G210 -> 0 | K26: ='DETAIL 2026'!H210 -> 0.007548686 | L26: ='DETAIL 2026'!I210 -> 0 | M26: ='DETAIL 2026'!J210 -> 0.0092225746
C27: h. Repair Rate Press Line | D27: Monthly | E27: 0.01 | G27: ='DETAIL 2026'!D231 -> 0.00611375 | H27: ='DETAIL 2026'!E231 -> 0.0096626104 | I27: ='DETAIL 2026'!F231 -> 0.0084733668 | J27: ='DETAIL 2026'!G231 -> 0.0064948579 | K27: ='DETAIL 2026'!H231 -> 0.0075743869 | L27: ='DETAIL 2026'!I231 -> 0.0088782085 | M27: ='DETAIL 2026'!J231 -> 0.010419599
C28: i. Repair Rate Press Line | D28: Ytd | E28: 0.01 | G28: ='DETAIL 2026'!D236 -> 0.00611375 | H28: ='DETAIL 2026'!E236 -> 0.0080866872 | I28: ='DETAIL 2026'!F236 -> 0.0081969804 | J28: ='DETAIL 2026'!G236 -> 0.0077130363 | K28: ='DETAIL 2026'!H236 -> 0.0076839014 | L28: ='DETAIL 2026'!I236 -> 0.0078918657 | M28: ='DETAIL 2026'!J236 -> 0.0082384401
C30: 2. Reject Rate Press Line
C31: a. Reject Rate Press A | D31: Monthly | E31: 0.0002 | G31: ='DETAIL 2026'!D85 -> 3.5901164e-05 | H31: ='DETAIL 2026'!E85 -> 0.00017350568 | I31: ='DETAIL 2026'!F85 -> 0.00055342298 | J31: ='DETAIL 2026'!G85 -> 5.9642295e-05 | K31: ='DETAIL 2026'!H85 -> 0.00010300252 | L31: ='DETAIL 2026'!I85 -> 0.00010033948 | M31: ='DETAIL 2026'!J85 -> 0.00014389524
C32: b. Reject Rate Press B | D32: Monthly | E32: 0.0002 | G32: ='DETAIL 2026'!D106 -> 5.9681895e-05 | H32: ='DETAIL 2026'!E106 -> 0.00019581501 | I32: ='DETAIL 2026'!F106 -> 0.00026928587 | J32: ='DETAIL 2026'!G106 -> 0 | K32: ='DETAIL 2026'!H106 -> 0.00010064293 | L32: ='DETAIL 2026'!I106 -> 0.00010697913 | M32: ='DETAIL 2026'!J106 -> 0.00020823884
C33: c. Reject Rate Press C | D33: Monthly | E33: 0.0002 | G33: ='DETAIL 2026'!D127 -> 0.0024075189 | H33: ='DETAIL 2026'!E127 -> 0.0020155002 | I33: ='DETAIL 2026'!F127 -> 0.00052030941 | J33: ='DETAIL 2026'!G127 -> 0.00014414414 | K33: ='DETAIL 2026'!H127 -> 0.00023810232 | L33: ='DETAIL 2026'!I127 -> 0.00023089356 | M33: ='DETAIL 2026'!J127 -> 0.00024899365
C34: d. Reject Rate Press D | D34: Monthly | E34: 0.0002 | G34: ='DETAIL 2026'!D148 -> 0.00014340915 | H34: ='DETAIL 2026'!E148 -> 0.00010467211 | I34: ='DETAIL 2026'!F148 -> 0.00019332824 | J34: ='DETAIL 2026'!G148 -> 8.4269426e-06 | K34: ='DETAIL 2026'!H148 -> 0.00011021578 | L34: ='DETAIL 2026'!I148 -> 5.5889339e-05 | M34: ='DETAIL 2026'!J148 -> 0.0002453929
C35: e. Reject Rate Press E | D35: Monthly | E35: 0.0002 | G35: ='DETAIL 2026'!D169 -> 0.00028374161 | H35: ='DETAIL 2026'!E169 -> 0.0011425307 | I35: ='DETAIL 2026'!F169 -> 0.0015196056 | J35: ='DETAIL 2026'!G169 -> 0.0007808309 | K35: ='DETAIL 2026'!H169 -> 0.0011490777 | L35: ='DETAIL 2026'!I169 -> 0.00061996932 | M35: ='DETAIL 2026'!J169 -> 0.00090981242
C36: f. Reject Rate Press F | D36: Monthly | E36: 0.0002 | G36: ='DETAIL 2026'!D190 -> 0.00038173805 | H36: ='DETAIL 2026'!E190 -> 0.00063008617 | I36: ='DETAIL 2026'!F190 -> 0.00046199908 | J36: ='DETAIL 2026'!G190 -> 0.00071137947 | K36: ='DETAIL 2026'!H190 -> 0.00068567614 | L36: ='DETAIL 2026'!I190 -> 0.00035060655 | M36: ='DETAIL 2026'!J190 -> 0.00057979345
C37: g. Reject Rate Press K | D37: Monthly | E37: 0.0002 | G37: ='DETAIL 2026'!D211 -> 0.00025068772 | H37: ='DETAIL 2026'!E211 -> 0 | I37: ='DETAIL 2026'!F211 -> 0 | J37: ='DETAIL 2026'!G211 -> 1.4592241e-05 | K37: ='DETAIL 2026'!H211 -> 1.9235044e-05 | L37: ='DETAIL 2026'!I211 -> 0 | M37: ='DETAIL 2026'!J211 -> 0.0010103922
C38: h. Reject Rate Press Line | D38: Monthly | E38: 0.0002 | G38: ='DETAIL 2026'!D232 -> 0.00026287134 | H38: ='DETAIL 2026'!E232 -> 0.00035313768 | I38: ='DETAIL 2026'!F232 -> 0.00041307552 | J38: ='DETAIL 2026'!G232 -> 0.0002017511 | K38: ='DETAIL 2026'!H232 -> 0.00027342884 | L38: ='DETAIL 2026'!I232 -> 0.00017760484 | M38: ='DETAIL 2026'!J232 -> 0.00056310113
C39: i. Reject Rate Press Line | D39: Ytd | E39: 0.0002 | G39: ='DETAIL 2026'!D237 -> 0.00026287134 | H39: ='DETAIL 2026'!E237 -> 0.00031305359 | I39: ='DETAIL 2026'!F237 -> 0.00034158299 | J39: ='DETAIL 2026'!G237 -> 0.00030182627 | K39: ='DETAIL 2026'!H237 -> 0.000295859 | L39: ='DETAIL 2026'!I237 -> 0.00027526744 | M39: ='DETAIL 2026'!J237 -> 0.00031473196
O42: Bekasi, 01 Agustus 2026
O43: Approved | Q43: Checked
O48: Ka. Div | Q48: Ka. Dept.

Sheet DETAIL 2026
A1: STROKE/TPT = GSPH
A2: BULAN | D2: JAN | E2: FEB | F2: MAR | G2: APR | H2: MEI | I2: JUN | J2: JUL | K2: AGU | L2: SEP | M2: OKT | N2: NOV | O2: DES
A4: GSPH | B4: A LINE | D4: JAN | E4: FEB | F4: MAR | G4: APR | H4: MEI | I4: JUN | J4: JUL | K4: AGU | L4: SEP | M4: OKT | N4: NOV | O4: DES
C5: TPT (menit) | D5: 76082 | E5: 73862 | F5: 65188 | G5: 82770 | H5: 72550 | I5: 77113 | J5: 75668
C6: Stroke | D6: 558212 | E6: 552904 | F6: 493440 | G6: 632918 | H6: 550636 | I6: 587531 | J6: 576992
C7: GSPH | D7: =D6/D5*60 -> 440.21871 | E7: =E6/E5*60 -> 449.13812 | F7: =F6/F5*60 -> 454.16948 | G7: =G6/G5*60 -> 458.80246 | H7: =H6/H5*60 -> 455.3847 | I7: =I6/I5*60 -> 457.14549 | J7: =J6/J5*60 -> 457.51863 | K7: =K6/K5*60 -> #DIV/0! | ... O7: =O6/O5*60 -> #DIV/0!
B8: YTD | C8: TPT (menit) | D8: =D5 -> 76082 | E8: =E5+D8 -> 149944 | F8: =F5+E8 -> 215132 | G8: =G5+F8 -> 297902 | H8: =H5+G8 -> 370452 | I8: =I5+H8 -> 447565 | J8: =J5+I8 -> 523233 | K8: =K5+J8 -> 523233 | L8: =L5+K8 -> 523233 | ... O8: =O5+N8 -> 523233
C9: Stroke | D9: =D6 -> 558212 | E9: =E6+D9 -> 1111116 | F9: =F6+E9 -> 1604556 | G9: =G6+F9 -> 2237474 | H9: =H6+G9 -> 2788110 | I9: =I6+H9 -> 3375641 | J9: =J6+I9 -> 3952633 | K9: =K6+J9 -> 3952633 | L9: =L6+K9 -> 3952633 | ... O9: =O6+N9 -> 3952633
C10: GSPH | D10: =D9/D8*60 -> 440.21871 | E10: =E9/E8*60 -> 444.61239 | F10: =F9/F8*60 -> 447.50832 | G10: =G9/G8*60 -> 450.64632 | H10: =H9/H8*60 -> 451.57429 | I10: =I9/I8*60 -> 452.53418 | J10: =J9/J8*60 -> 453.25501 | K10: =K9/K8*60 -> 453.25501 | ... O10: =O9/O8*60 -> 453.25501
B12: B LINE | D12: JAN | E12: FEB | F12: MAR | G12: APR | H12: MEI | I12: JUN | J12: JUL | K12: AGU | L12: SEP | M12: OKT | N12: NOV | O12: DES
C13: TPT (menit) | D13: 104701 | E13: 107558 | F13: 81995 | G13: 109049 | H13: 85355 | I13: 94421 | J13: 100632
C14: Stroke | D14: 826538 | E14: 815966 | F14: 606486 | G14: 753050 | H14: 631602 | I14: 693055 | J14: 740435
C15: GSPH | D15: =D14/D13*60 -> 473.65622 | E15: =E14/E13*60 -> 455.1773 | F15: =F14/F13*60 -> 443.7973 | G15: =G14/G13*60 -> 414.33667 | H15: =H14/H13*60 -> 443.98243 | I15: =I14/I13*60 -> 440.40309 | J15: =J14/J13*60 -> 441.4709 | K15: =K14/K13*60 -> #DIV/0! | ... O15: =O14/O13*60 -> #DIV/0!
B16: YTD | C16: TPT (menit) | D16: =D13 -> 104701 | E16: =E13+D16 -> 212259 | F16: =F13+E16 -> 294254 | G16: =G13+F16 -> 403303 | H16: =H13+G16 -> 488658 | I16: =I13+H16 -> 583079 | J16: =J13+I16 -> 683711 | K16: =K13+J16 -> 683711 | L16: =L13+K16 -> 683711 | ... O16: =O13+N16 -> 683711
C17: Stroke | D17: =D14 -> 826538 | E17: =E14+D17 -> 1642504 | F17: =F14+E17 -> 2248990 | G17: =G14+F17 -> 3002040 | H17: =H14+G17 -> 3633642 | I17: =I14+H17 -> 4326697 | J17: =J14+I17 -> 5067132 | K17: =K14+J17 -> 5067132 | L17: =L14+K17 -> 5067132 | ... O17: =O14+N17 -> 5067132
C18: GSPH | D18: =D17/D16*60 -> 473.65622 | E18: =E17/E16*60 -> 464.2924 | F18: =F17/F16*60 -> 458.58136 | G18: =G17/G16*60 -> 446.61805 | H18: =H17/H16*60 -> 446.15768 | I18: =I17/I16*60 -> 445.22581 | J18: =J17/J16*60 -> 444.67314 | K18: =K17/K16*60 -> 444.67314 | ... O18: =O17/O16*60 -> 444.67314
B20: C LINE | D20: JAN | E20: FEB | F20: MAR | G20: APR | H20: MEI | I20: JUN | J20: JUL | K20: AGU | L20: SEP | M20: OKT | N20: NOV | O20: DES
C21: TPT (menit) | D21: 52708 | E21: 51468 | F21: 44641 | G21: 59596 | H21: 50923.32 | I21: 59588 | J21: 42560
C22: Stroke | D22: 171603 | E22: 184165 | F22: 152677 | G22: 212564 | H22: 179296 | I22: 199972 | J22: 149068
C23: GSPH | D23: =D22/D21*60 -> 195.34378 | E23: =E22/E21*60 -> 214.69457 | F23: =F22/F21*60 -> 205.20642 | G23: =G22/G21*60 -> 214.00497 | H23: =H22/H21*60 -> 211.2541 | I23: =I22/I21*60 -> 201.35464 | J23: =J22/J21*60 -> 210.15226 | K23: =K22/K21*60 -> #DIV/0! | ... O23: =O22/O21*60 -> #DIV/0!
B24: YTD | C24: TPT (menit) | D24: =D21 -> 52708 | E24: =E21+D24 -> 104176 | F24: =F21+E24 -> 148817 | G24: =G21+F24 -> 208413 | H24: =H21+G24 -> 259336.32 | I24: =I21+H24 -> 318924.32 | J24: =J21+I24 -> 361484.32 | K24: =K21+J24 -> 361484.32 | L24: =L21+K24 -> 361484.32 | ... O24: =O21+N24 -> 361484.32
C25: Stroke | D25: =D22 -> 171603 | E25: =E22+D25 -> 355768 | F25: =F22+E25 -> 508445 | G25: =G22+F25 -> 721009 | H25: =H22+G25 -> 900305 | I25: =I22+H25 -> 1100277 | J25: =J22+I25 -> 1249345 | K25: =K22+J25 -> 1249345 | L25: =L22+K25 -> 1249345 | ... O25: =O22+N25 -> 1249345
C26: GSPH | D26: =D25/D24*60 -> 195.34378 | E26: =E25/E24*60 -> 204.90401 | F26: =F25/F24*60 -> 204.99473 | G26: =G25/G24*60 -> 207.57122 | H26: =H25/H24*60 -> 208.29439 | I26: =I25/I24*60 -> 206.99776 | J26: =J25/J24*60 -> 207.36916 | K26: =K25/K24*60 -> 207.36916 | ... O26: =O25/O24*60 -> 207.36916
B28: D LINE | D28: JAN | E28: FEB | F28: MAR | G28: APR | H28: MEI | I28: JUN | J28: JUL | K28: AGU | L28: SEP | M28: OKT | N28: NOV | O28: DES | R28: PRESS LINE | T28: JAN | U28: FEB | V28: MAR | W28: APR | X28: MEI | Y28: JUN | Z28: JUL | AA28: AGU | AB28: SEP | AC28: OKT | AD28: NOV | AE28: DES
C29: TPT (menit) | D29: 70834.867 | E29: 87950 | F29: 47767 | G29: 101985 | H29: 83289 | I29: 75295 | J29: 84936 | S29: TPT (menit) | T29: =D5+D13+D21+D29 -> 304325.87 | U29: =E5+E13+E21+E29 -> 320838 | V29: =F5+F13+F21+F29 -> 239591 | W29: =G5+G13+G21+G29 -> 353400 | X29: =H5+H13+H21+H29 -> 292117.32 | Y29: =I5+I13+I21+I29 -> 306417 | Z29: =J5+J13+J21+J29 -> 303796 | AA29: =K5+K13+K21+K29 -> 0 | ... AE29: =O5+O13+O21+O29 -> 0
C30: Stroke | D30: 509456 | E30: 652400 | F30: 356886 | G30: 730316 | H30: 611266 | I30: 536594 | J30: 623084 | S30: Stroke | T30: =D6+D14+D22+D30 -> 2065809 | U30: =E6+E14+E22+E30 -> 2205435 | V30: =F6+F14+F22+F30 -> 1609489 | W30: =G6+G14+G22+G30 -> 2328848 | X30: =H6+H14+H22+H30 -> 1972800 | Y30: =I6+I14+I22+I30 -> 2017152 | Z30: =J6+J14+J22+J30 -> 2089579 | AA30: =K6+K14+K22+K30 -> 0 | ... AE30: =O6+O14+O22+O30 -> 0
C31: GSPH | D31: =D30/D29*60 -> 431.52986 | E31: =E30/E29*60 -> 445.07106 | F31: =F30/F29*60 -> 448.28354 | G31: =G30/G29*60 -> 429.66083 | H31: =H30/H29*60 -> 440.34578 | I31: =I30/I29*60 -> 427.59333 | J31: =J30/J29*60 -> 440.15541 | K31: =K30/K29*60 -> #DIV/0! | ... O31: =O30/O29*60 -> #DIV/0! | S31: GSPH | T31: =T30/T29*60 -> 407.28888 | U31: =U30/U29*60 -> 412.43899 | V31: =V30/V29*60 -> 403.05913 | W31: =W30/W29*60 -> 395.39015 | X31: =X30/X29*60 -> 405.20706 | Y31: =Y30/Y29*60 -> 394.98174 | Z31: =Z30/Z29*60 -> 412.69385 | AA31: =AA30/AA29*60 -> #DIV/0! | ... AE31: =AE30/AE29*60 -> #DIV/0!
B32: YTD | C32: TPT (menit) | D32: =D29 -> 70834.867 | E32: =E29+D32 -> 158784.87 | F32: =F29+E32 -> 206551.87 | G32: =G29+F32 -> 308536.87 | H32: =H29+G32 -> 391825.87 | I32: =I29+H32 -> 467120.87 | J32: =J29+I32 -> 552056.87 | K32: =K29+J32 -> 552056.87 | L32: =L29+K32 -> 552056.87 | ... O32: =O29+N32 -> 552056.87 | R32: YTD | S32: TPT (menit) | T32: =T29 -> 304325.87 | U32: =U29+T32 -> 625163.87 | V32: =V29+U32 -> 864754.87 | W32: =W29+V32 -> 1218154.9 | X32: =X29+W32 -> 1510272.2 | Y32: =Y29+X32 -> 1816689.2 | Z32: =Z29+Y32 -> 2120485.2 | AA32: =AA29+Z32 -> 2120485.2 | AB32: =AB29+AA32 -> 2120485.2 | ... AE32: =AE29+AD32 -> 2120485.2
C33: Stroke | D33: =D30 -> 509456 | E33: =E30+D33 -> 1161856 | F33: =F30+E33 -> 1518742 | G33: =G30+F33 -> 2249058 | H33: =H30+G33 -> 2860324 | I33: =I30+H33 -> 3396918 | J33: =J30+I33 -> 4020002 | K33: =K30+J33 -> 4020002 | L33: =L30+K33 -> 4020002 | ... O33: =O30+N33 -> 4020002 | S33: Stroke | T33: =T30 -> 2065809 | U33: =U30+T33 -> 4271244 | V33: =V30+U33 -> 5880733 | W33: =W30+V33 -> 8209581 | X33: =X30+W33 -> 10182381 | Y33: =Y30+X33 -> 12199533 | Z33: =Z30+Y33 -> 14289112 | AA33: =AA30+Z33 -> 14289112 | AB33: =AB30+AA33 -> 14289112 | ... AE33: =AE30+AD33 -> 14289112
C34: GSPH | D34: =D33/D32*60 -> 431.52986 | E34: =E33/E32*60 -> 439.03025 | F34: =F33/F32*60 -> 441.17016 | G34: =G33/G32*60 -> 437.36582 | H34: =H33/H32*60 -> 437.99926 | I34: =I33/I32*60 -> 436.32193 | J34: =J33/J32*60 -> 436.91173 | K34: =K33/K32*60 -> 436.91173 | ... O34: =O33/O32*60 -> 436.91173 | S34: GSPH | T34: =T33/T32*60 -> 407.28888 | U34: =U33/U32*60 -> 409.93195 | V34: =V33/V32*60 -> 408.02775 | W34: =W33/W32*60 -> 404.36144 | X34: =X33/X32*60 -> 404.525 | Y34: =Y33/Y32*60 -> 402.91536 | Z34: =Z33/Z32*60 -> 404.3163 | AA34: =AA33/AA32*60 -> 404.3163 | ... AE34: =AE33/AE32*60 -> 404.3163
B36: E LINE | D36: JAN | E36: FEB | F36: MAR | G36: APR | H36: MEI | I36: JUN | J36: JUL | K36: AGU | L36: SEP | M36: OKT | N36: NOV | O36: DES
C37: TPT (menit) | D37: 77588 | E37: 84832.573 | F37: 67324.6 | G37: 70722.867 | H37: 64432 | I37: 73616.2 | J37: 14780.9
C38: Stroke | D38: 550240 | E38: 574944 | F38: 461608 | G38: 483532 | H38: 445292 | I38: 534388 | J38: 59123.6
C39: GSPH | D39: =D38/D37*60 -> 425.5091 | E39: =E38/E37*60 -> 406.6438 | F39: =F38/F37*60 -> 411.38722 | G39: =G38/G37*60 -> 410.2198 | H39: =H38/H37*60 -> 414.66228 | I39: =I38/I37*60 -> 435.54652 | J39: =J38/J37*60 -> 240 | K39: =K38/K37*60 -> #DIV/0! | ... O39: =O38/O37*60 -> #DIV/0!
B40: YTD | C40: TPT (menit) | D40: =D37 -> 77588 | E40: =E37+D40 -> 162420.57 | F40: =F37+E40 -> 229745.17 | G40: =G37+F40 -> 300468.04 | H40: =H37+G40 -> 364900.04 | I40: =I37+H40 -> 438516.24 | J40: =J37+I40 -> 453297.14 | K40: =K37+J40 -> 453297.14 | L40: =L37+K40 -> 453297.14 | ... O40: =O37+N40 -> 453297.14
C41: Stroke | D41: =D38 -> 550240 | E41: =E38+D41 -> 1125184 | F41: =F38+E41 -> 1586792 | G41: =G38+F41 -> 2070324 | H41: =H38+G41 -> 2515616 | I41: =I38+H41 -> 3050004 | J41: =J38+I41 -> 3109127.6 | K41: =K38+J41 -> 3109127.6 | L41: =L38+K41 -> 3109127.6 | ... O41: =O38+N41 -> 3109127.6
C42: GSPH | D42: =D41/D40*60 -> 425.5091 | E42: =E41/E40*60 -> 415.65572 | F42: =F41/F40*60 -> 414.40488 | G42: =G41/G40*60 -> 413.41981 | H42: =H41/H40*60 -> 413.6392 | I42: =I41/I40*60 -> 417.3169 | J42: =J41/J40*60 -> 411.53504 | K42: =K41/K40*60 -> 411.53504 | ... O42: =O41/O40*60 -> 411.53504
B44: F LINE | D44: JAN | E44: FEB | F44: MAR | G44: APR | H44: MEI | I44: JUN | J44: JUL | K44: AGU | L44: SEP | M44: OKT | N44: NOV | O44: DES
C45: TPT (menit) | D45: 77766.8 | E45: 83559.4 | F45: 59849.6 | G45: 80207.6 | H45: 74808 | I45: 76053.44 | J45: 17202.5
C46: Stroke | D46: 665120 | E46: 703492 | F46: 524052 | G46: 697812 | H46: 639744 | I46: 663732 | J46: 68810
...

Sheet GSPH REPAIR REJECT 2026 (2)
B2: CONTROL ITEM | C2: DESCRIPTION | D2: TARGET KPI | E2: TARGET | F2: ACHIEVEMENT
F3: JAN | G3: FEB | H3: MAR | I3: APR | J3: MAY | K3: JUN | L3: JUL
B4: 1. Productivity | C4: 1. GSPH
C5: a. Press A | D5: 540 | E5: 537.35408 | F5: 440.21871 | G5: 449.13812 | H5: 454.16948 | I5: 458.80246 | J5: 455.3847 | K5: 457.14549 | L5: 457.51863
C6: b. Press B | D6: 550 | E6: 565.84342 | F6: 473.65622 | G6: 455.1773 | H6: 443.7973 | I6: 414.33667 | J6: 443.98243 | K6: 440.40309 | L6: 441.4709
C7: c. Press C | D7: 355 | E7: 255.52571 | F7: 195.34378 | G7: 214.69457 | H7: 205.20642 | I7: 214.00497 | J7: 211.2541 | K7: 201.35464 | L7: 210.15226
C8: d. Press D | D8: 535 | E8: 537.63713 | F8: 431.52986 | G8: 445.07106 | H8: 448.28354 | I8: 429.66083 | J8: 440.34578 | K8: 427.59333 | L8: 440.15541
B10: 2. Quality | C10: 1. Repair Rate Press Line
C11: a. Repair Rate Press A | D11: 0.01 | F11: 0.0021540698 | G11: 0.00052051705 | H11: 0.00022372418 | I11: 0.00181909 | J11: 0.00011330278 | K11: 0.0027676974 | L11: 0.0012470921
C12: b. Repair Rate Press B | D12: 0.01 | F12: 0.0059926049 | G12: 0.017598564 | H12: 0.014827985 | I12: 0.0066699599 | J12: 0.0008140237 | K12: 0.01418732 | L12: 0.0092252659
C13: c. Repair Rate Press C | D13: 0.01 | F13: 0.037548035 | G13: 0.035991074 | H13: 0.032952929 | I13: 0.038486486 | J13: 0.030477098 | K13: 0.040752713 | L13: 0.037100054
C14: d. Repair Rate Press D | D14: 0.01 | F14: 0.012898857 | G14: 0.018018557 | H14: 0.015369595 | I14: 0.0029494299 | J14: 0.0056271278 | K14: 0.0056098924 | L14: 0.010168842
C16: 2. Reject Rate Press Line
C17: a. Reject Rate Press A | D17: 0.0002 | F17: 3.5901164e-05 | G17: 0.00017350568 | H17: 0.00055342298 | I17: 5.9642295e-05 | J17: 0.00010300252 | K17: 0.00010033948 | L17: 0.00014389524
C18: b. Reject Rate Press B | D18: 0.0002 | F18: 5.9681895e-05 | G18: 0.00019581501 | H18: 0.00026928587 | I18: 0 | J18: 0.00010064293 | K18: 0.00010697913 | L18: 0.00020823884
C19: c. Reject Rate Press C | D19: 0.0002 | F19: 0.0024075189 | G19: 0.0020155002 | H19: 0.00052030941 | I19: 0.00014414414 | J19: 0.00023810232 | K19: 0.00023089356 | L19: 0.00024899365
C20: d. Reject Rate Press D | D20: 0.0002 | F20: 0.00014340915 | G20: 0.00010467211 | H20: 0.00019332824 | I20: 8.4269426e-06 | J20: 0.00011021578 | K20: 5.5889339e-05 | L20: 0.0002453929

Sheet Sheet1
G2: DATA YTD JUNI 2024
I4: TARGET | J4: GSPH YTD
G5: GSPH | H5: PRESS A | I5: 538 | J5: 495.2134
H6: PRESS B | I6: 569 | J6: 536.03481
H7: PRESS C | I7: 264 | J7: 193.10993
H8: PRESS D | I8: 540 | J8: 519.24702
G10: REPAIR | H10: PRESS A | I10: 0.0125 | J10: 0.02892208
H11: PRESS B | I11: 0.0125 | J11: 0.025623931
H12: PRESS C | I12: 0.0125 | J12: 0.075043184
H13: PRESS D | I13: 0.0125 | J13: 0.00040737245
G15: REJECT | H15: PRESS A | I15: 0.0002 | J15: 0.00027353106
H16: PRESS B | I16: 0.0002 | J16: 7.3559623e-05
H17: PRESS C | I17: 0.0002 | J17: 0.0018414506
H18: PRESS D | I18: 0.0002 | J18: 5.6634706e-05

Sheet PICA GSPH
B1: PICA JANUARI 2026
B3: PROBLEM | C3: TARGET | D3: ACTUAL | E3: PROBLEM | F3: ACTION | G3: PIC | H3: TARGET
B5: GSPH of A line was not achieved | C5: 540 | D5: 440.21871
B6: GSPH of B line was not achieved | C6: 550 | D6: 473.65622
B7: GSPH of C line was not achieved | C7: 355 | D7: 195.34378
B8: GSPH of D line was not achieved | C8: 535 | D8: 431.52986

Sheet PICA GSPH FEB
B1: PICA FEBRUARI 2026
B3: PROBLEM | C3: TARGET | D3: ACTUAL | E3: PROBLEM | F3: ACTION | G3: PIC | H3: TARGET
B5: GSPH of A line was not achieved | C5: 540 | D5: 449.13812
B6: GSPH of B line was not achieved | C6: 550 | D6: 455.1773
B7: GSPH of C line was not achieved | C7: 355 | D7: 214.69457
B8: GSPH of D line was not achieved | C8: 535 | D8: 445.07106

Sheet PICA GSPH MAR
B1: PICA MARET 2026
B3: PROBLEM | C3: TARGET | D3: ACTUAL | E3: PROBLEM | F3: ACTION | G3: PIC | H3: TARGET
B5: GSPH of A line was not achieved | C5: 540 | D5: 454.16948
B6: GSPH of B line was not achieved | C6: 550 | D6: 443.7973
B7: GSPH of C line was not achieved | C7: 355 | D7: 205.20642
B8: GSPH of D line was not achieved | C8: 535 | D8: 448.28354

Sheet PICA GSPH APRIL
B1: PICA APRIL 2026
B3: PROBLEM | C3: TARGET | D3: ACTUAL | E3: PROBLEM | F3: ACTION | G3: PIC | H3: TARGET
B5: GSPH of A line was not achieved | C5: 540 | D5: 458.80246
B6: GSPH of B line was not achieved | C6: 550 | D6: 414.33667
B7: GSPH of C line was not achieved | C7: 355 | D7: 214.00497
B8: GSPH of D line was not achieved | C8: 535 | D8: 429.66083

Sheet PICA REPAIR
B1: PICA JULI 2024
B3: PROBLEM | C3: TARGET | D3: ACTUAL | E3: PROBLEM | F3: ACTION | G3: PIC | H3: TARGET
B5: Repair rate of A line was not achieved | C5: 0.0125 | D5: 0.0436 | E5: The OP-10 drawing results on the G-series die experienced waves because the pull on the bead was uneven. | F5: Re-FAT the OP-10 (drawing) die to find the standard cushion pressure in the range -10% to +30% (range 40%). | G5: June, 2024 | H5: Bioma Cakrawala (BCA)
B6: Repair rate of B line was not achieved | C6: 0.0125 | D6: 0.0232 | E6: There is a repair hole on PV-023BS because the leader did not implement the SCW (stop call wait) system with his superiors. | F6: Refreshment of all leaders with leader roles by emphasizing the SCW system in the production process line. | G6: June, 2024 | H6: Bioma Cakrawala (BCA)
B7: Repair rate of C line was not achieved | C7: 0.0125 | D7: 0.0898 | E7: Repair rate Line C was not achieved because there is scratch & wave problem on somes dies. | F7: Standarization of dies following production machine for wave problem. | G7: July, 2024 | H7: Bayu Prakosa (BPR)
B8: REPAIR RATE PRESS – E LINE | C8: 0.0125 | D8: 0.016 | E8: 1. Gomikami originating from internal problems (RM, Dies, Gram) and from external (dust) | F8: 1. Initial cleaning RM, Preventive maintenance Dies & minimize dust sources by closing the factory gap. Cleaning Factory on DOT/HOT. Additional Momban Gate for automatic open-closed. | G8: WVA | H8: 45491
E9: 2. Hardchrome dies start to peel off due to lifetime of use above 2 years. | F9: 2. Propose Re-newal dies that have been peeled off.
B10: REPAIR RATE PRESS – F LINE | C10: 0.0125 | D10: 0.0013 | E10: 1. Gomikami originating from internal problems (RM, Dies, Gram) and from external (dust) | F10: 1. Initial cleaning RM, Preventive maintenance Dies & minimize dust sources by closing the factory gap. Cleaning Factory on DOT/HOT. Additional Momban Gate for automatic open-closed. | G10: WVA | H10: 45491
G11: WVA | H11: 45498
E12: 2. Hardchrome dies start to peel off due to lifetime of use above 2 years. | F12: 2. Propose Re-Hardchrome dies that have been peeled off.
B13: REPAIR RATE PRESS – K LINE | C13: 0.0125 | D13: 0.0326 | E13: 1. Gomikami originating from internal problems (RM, Dies, Gram) and from external (dust) | F13: 1. Initial cleaning RM, Preventive maintenance Dies & minimize dust sources by closing the factory gap. Cleaning Factory on DOT/HOT. Additional Momban Gate for automatic open-closed. | G13: WVA | H13: 45498
E14: 2. Hardchrome dies start to peel off due to lifetime of use above 2 years. | F14: 2. Propose Re-Hardchrome dies that have been peeled off. | G14: WVA | H14: 45491

Sheet PICA REJECT
B1: PICA JUNI 2024
B3: PROBLEM | C3: TARGET | D3: ACTUAL | E3: PROBLEM | F3: ACTION | G3: PIC | H3: TARGET
B5: Reject rate of C line was not achieved | C5: 0.0002 | D5: 0.0022 | E5: Rejection rate Line C was not achieved because there is neck problem of K-4078. | F5: 1. Standardzation of dies following production machine. 2. Re-FAT dies for problem neck and wave. | G5: June, 2024 | H5: Bioma Cakrawala (BCA)
B6: REJECT RATE – E LINE | C6: 0.0005 | D6: 0.0005 | E6: Several dies still problem unstable process, surface hardchrome NG (Neck, Crack, Scratch). Poor of spare part management. | F6: 1. Temporary action, polishing dies after process, initial cleaning before process. | G6: WVA | H6: 45491
F7: 2. Develop Management spare part for dies. | G7: EHU | H7: 45498
B8: REJECT RATE – F LINE | C8: 0.0005 | D8: 0 | E8: Several dies still problem unstable process, surface hardchrome NG (Neck, Crack, Scratch). Poor of spare part management. | F8: 1. Temporary action, polishing dies after process, initial cleaning before process. | G8: WVA | H8: 45491
F9: 2. Develop Management spare part for dies. | G9: EHU | H9: 45498
B10: REJECT RATE – K LINE | C10: 0.0005 | D10: 0.0034 | E10: Several dies still problem unstable process, surface hardchrome NG (Neck, Crack, Scratch). Poor of spare part management. | F10: 1. Temporary action, polishing dies after process, initial cleaning before process. | G10: WVA | H10: 45491
F11: 2. Develop Management spare part for dies. | G11: EHU | H11: 45498

Sheet QTY A
A1: DATA DETAIL QTY STAMPING - 2024
A2: NO | B2: MAT'L NUMBER | C2: DESCRIPTION | D2: LINE | F2: JANUARI | J2: FEBRUARI | N2: MARET | R2: APRIL | V2: MEI | Z2: JUNI | AD2: JULI | AH2: AGUSTUS | AL2: SEPTEMBER | AP2: OKTOBER | AT2: NOVEMBER | AX2: DESEMBER
F3: OK | G3: REPAIR | H3: REJECT | J3: OK | K3: REPAIR | L3: REJECT | N3: OK | O3: REPAIR | P3: REJECT | R3: OK | S3: REPAIR | T3: REJECT | V3: OK | W3: REPAIR | X3: REJECT | Z3: OK | AA3: REPAIR | AB3: REJECT | AD3: OK | AE3: REPAIR | AF3: REJECT | AH3: OK | AI3: REPAIR | AJ3: REJECT | AL3: OK | AM3: REPAIR | AN3: REJECT | AP3: OK | AQ3: REPAIR | AR3: REJECT | AT3: OK | AU3: REPAIR | AV3: REJECT | AX3: OK | AY3: REPAIR | AZ3: REJECT
A4: 1 | B4: D58213 BZ130 | C4: AAS-054=REINF CTR FLOOR PANEL | D4: PRESS A | F4: 8760 | G4: 0 | H4: 0 | J4: 9000 | K4: 0 | L4: 0 | N4: 9060 | O4: 0 | P4: 0 | R4: 5370 | S4: 0 | T4: 0 | V4: 9120 | W4: 0 | X4: 0 | Z4: 7620 | AA4: 0 | AB4: 0 | AC4: 1 | AD4: =VLOOKUP(B4,[4]PCS!$D$1:$E$65536,2,0) -> 8297 | AE4: =VLOOKUP(B4,[4]PCS!$D$1:$F$65536,3,0) -> 0 | AF4: =VLOOKUP(B4,[4]PCS!$D$1:$G$65536,4,0) -> 0 | AG4: 1 | AH4: =VLOOKUP(C4,[5]Sheet1!$C$1:$D$65536,2,0) -> 8263 | AI4: =VLOOKUP(C4,[5]Sheet1!$C$1:$F$65536,3,0) -> 0 | AJ4: =VLOOKUP(C4,[5]Sheet1!$C$1:$F$65536,4,0) -> 0
A5: 2 | B5: D61343 BZ180 | C5: AAS-058=PILLAR CTR BODY INNER RH | D5: PRESS A | F5: 8400 | G5: 0 | H5: 0 | J5: 8600 | K5: 0 | L5: 0 | N5: 9000 | O5: 0 | P5: 0 | R5: 6680 | S5: 0 | T5: 0 | V5: 9100 | W5: 0 | X5: 0 | Z5: 7218 | AA5: 0 | AB5: 0 | AC5: 1 | AD5: =VLOOKUP(B5,[4]PCS!$D$1:$E$65536,2,0) -> 7950 | AE5: =VLOOKUP(B5,[4]PCS!$D$1:$F$65536,3,0) -> 0 | AF5: =VLOOKUP(B5,[4]PCS!$D$1:$G$65536,4,0) -> 0 | AG5: 1 | AH5: =VLOOKUP(C5,[5]Sheet1!$C$1:$D$65536,2,0) -> 8255 | AI5: =VLOOKUP(C5,[5]Sheet1!$C$1:$F$65536,3,0) -> 0 | AJ5: =VLOOKUP(C5,[5]Sheet1!$C$1:$F$65536,4,0) -> 0
A6: 3 | B6: D61344 BZ190 | C6: AAS-059=PILLAR CTR BODY INNER LH | D6: PRESS A | F6: 8400 | G6: 0 | H6: 0 | J6: 8600 | K6: 0 | L6: 0 | N6: 9000 | O6: 0 | P6: 0 | R6: 6680 | S6: 0 | T6: 0 | V6: 9100 | W6: 0 | X6: 0 | Z6: 7218 | AA6: 0 | AB6: 0 | AC6: 1 | AD6: =VLOOKUP(B6,[4]PCS!$D$1:$E$65536,2,0) -> 7950 | AE6: =VLOOKUP(B6,[4]PCS!$D$1:$F$65536,3,0) -> 0 | AF6: =VLOOKUP(B6,[4]PCS!$D$1:$G$65536,4,0) -> 0 | AG6: 1 | AH6: =VLOOKUP(C6,[5]Sheet1!$C$1:$D$65536,2,0) -> 8255 | AI6: =VLOOKUP(C6,[5]Sheet1!$C$1:$F$65536,3,0) -> 0 | AJ6: =VLOOKUP(C6,[5]Sheet1!$C$1:$F$65536,4,0) -> 0
A7: 4 | B7: D57454 BZ150 | C7: AES-006=MEMBER, FR FLOOR CROSS SIDE, LH | D7: PRESS A | F7: 11700 | G7: 0 | H7: 0 | J7: 13710 | K7: 0 | L7: 0 | N7: 10500 | O7: 0 | P7: 0 | R7: 8080 | S7: 0 | T7: 0 | V7: 15199 | W7: 51 | X7: 0 | AC7: 1 | AG7: 1
A8: 5 | B8: D61733 BZ040 | C8: AES-039=PANEL,ROOF SIDE INNER,FR RH | D8: PRESS A | F8: 11150 | G8: 0 | H8: 0 | J8: 12900 | K8: 0 | L8: 0 | N8: 9000 | O8: 0 | P8: 0 | R8: 8300 | S8: 0 | T8: 0 | V8: 14050 | W8: 0 | X8: 0 | Z8: 11740 | AA8: 0 | AB8: 0 | AC8: 1 | AD8: =VLOOKUP(B8,[4]PCS!$D$1:$E$65536,2,0) -> 11145 | AE8: =VLOOKUP(B8,[4]PCS!$D$1:$F$65536,3,0) -> 0 | AF8: =VLOOKUP(B8,[4]PCS!$D$1:$G$65536,4,0) -> 0 | AG8: 1 | AH8: =VLOOKUP(C8,[5]Sheet1!$C$1:$D$65536,2,0) -> 6474 | AI8: =VLOOKUP(C8,[5]Sheet1!$C$1:$F$65536,3,0) -> 0 | AJ8: =VLOOKUP(C8,[5]Sheet1!$C$1:$F$65536,4,0) -> 0
A9: 6 | B9: D61734 BZ040 | C9: AES-042=PANEL,ROOF SIDE INNER,FR LH | D9: PRESS A | F9: 11150 | G9: 0 | H9: 0 | J9: 12900 | K9: 0 | L9: 0 | N9: 9000 | O9: 0 | P9: 0 | R9: 8300 | S9: 0 | T9: 0 | V9: 14050 | W9: 0 | X9: 0 | Z9: 11740 | AA9: 0 | AB9: 0 | AC9: 1 | AD9: =VLOOKUP(B9,[4]PCS!$D$1:$E$65536,2,0) -> 11150 | AE9: =VLOOKUP(B9,[4]PCS!$D$1:$F$65536,3,0) -> 0 | AF9: =VLOOKUP(B9,[4]PCS!$D$1:$G$65536,4,0) -> 0 | AG9: 1 | AH9: =VLOOKUP(C9,[5]Sheet1!$C$1:$D$65536,2,0) -> 13074 | AI9: =VLOOKUP(C9,[5]Sheet1!$C$1:$F$65536,3,0) -> 0 | AJ9: =VLOOKUP(C9,[5]Sheet1!$C$1:$F$65536,4,0) -> 0
A10: 7 | B10: D57453 BZ100 | C10: AES-048=MEMBER, FR FLOOR CROSS SIDE, RH | D10: PRESS A | F10: 13050 | G10: 0 | H10: 0 | J10: 13200 | K10: 0 | L10: 0 | N10: 11850 | O10: 0 | P10: 0 | R10: 6700 | S10: 0 | T10: 0 | V10: 14170 | W10: 0 | X10: 18 | Z10: 12084 | AA10: 0 | AB10: 0 | AC10: 1 | AD10: =VLOOKUP(B10,[4]PCS!$D$1:$E$65536,2,0) -> 12830 | AE10: =VLOOKUP(B10,[4]PCS!$D$1:$F$65536,3,0) -> 0 | AF10: =VLOOKUP(B10,[4]PCS!$D$1:$G$65536,4,0) -> 0 | AG10: 1 | AH10: =VLOOKUP(C10,[5]Sheet1!$C$1:$D$65536,2,0) -> 14820 | AI10: =VLOOKUP(C10,[5]Sheet1!$C$1:$F$65536,3,0) -> 0 | AJ10: =VLOOKUP(C10,[5]Sheet1!$C$1:$F$65536,4,0) -> 1
A11: 8 | B11: DV61162 BZ081G2 | C11: G-002=PILLAR FR BODY INNER LH | D11: PRESS A | F11: 746 | G11: 127 | H11: 14 | J11: 708 | K11: 189 | L11: 1 | N11: 668 | O11: 101 | P11: 0 | R11: 578 | S11: 259 | T11: 0 | V11: 1017 | W11: 443 | X11: 0 | Z11: 1182 | AA11: 619 | AB11: 0 | AC11: 1 | AD11: =VLOOKUP(B11,[4]PCS!$D$1:$E$65536,2,0) -> 637 | AE11: =VLOOKUP(B11,[4]PCS!$D$1:$F$65536,3,0) -> 143 | AF11: =VLOOKUP(B11,[4]PCS!$D$1:$G$65536,4,0) -> 0 | AG11: 1 | AH11: =VLOOKUP(C11,[5]Sheet1!$C$1:$D$65536,2,0) -> 721 | AI11: =VLOOKUP(C11,[5]Sheet1!$C$1:$F$65536,3,0) -> 0 | AJ11: =VLOOKUP(C11,[5]Sheet1!$C$1:$F$65536,4,0) -> 21
A12: 9 | B12: DV61161 BZ240G3 | C12: G-003N=PILLAR, FR BODY, INNER RH | D12: PRESS A | F12: 117 | G12: 3 | H12: 0 | J12: 38 | K12: 22 | L12: 0 | R12: 141 | S12: 39 | T12: 0 | Z12: 694 | AA12: 280 | AB12: 0 | AC12: 1 | AD12: =VLOOKUP(B12,[4]PCS!$D$1:$E$65536,2,0) -> 2174 | AE12: =VLOOKUP(B12,[4]PCS!$D$1:$F$65536,3,0) -> 204 | AF12: =VLOOKUP(B12,[4]PCS!$D$1:$G$65536,4,0) -> 0 | AG12: 1 | AH12: =VLOOKUP(C12,[5]Sheet1!$C$1:$D$65536,2,0) -> 1800 | AI12: =VLOOKUP(C12,[5]Sheet1!$C$1:$F$65536,3,0) -> 0 | AJ12: =VLOOKUP(C12,[5]Sheet1!$C$1:$F$65536,4,0) -> 2
A13: 10 | B13: DV61162 BZ091G4 | C13: G-004=PILLAR FR BODY INNER LH | D13: PRESS A | F13: 709 | G13: 131 | H13: 0 | J13: 151 | K13: 209 | L13: 0 | N13: 268 | O13: 32 | P13: 0 | R13: 35 | S13: 415 | T13: 0 | V13: 720 | W13: 154 | X13: 0 | Z13: 836 | AA13: 278 | AB13: 0 | AC13: 1 | AD13: =VLOOKUP(B13,[4]PCS!$D$1:$E$65536,2,0) -> 527 | AE13: =VLOOKUP(B13,[4]PCS!$D$1:$F$65536,3,0) -> 136 | AF13: =VLOOKUP(B13,[4]PCS!$D$1:$G$65536,4,0) -> 0 | AG13: 1 | AH13: =VLOOKUP(C13,[5]Sheet1!$C$1:$D$65536,2,0) -> 67 | AI13: =VLOOKUP(C13,[5]Sheet1!$C$1:$F$65536,3,0) -> 0 | AJ13: =VLOOKUP(C13,[5]Sheet1!$C$1:$F$65536,4,0) -> 0
A14: 11 | B14: DV61162 BZ240G4 | C14: G-004N=PILLAR, FR BODY, INNER LH | D14: PRESS A | F14: 106 | G14: 14 | H14: 0 | J14: 45 | K14: 15 | L14: 0 | R14: 125 | S14: 55 | T14: 0 | Z14: 748 | AA14: 447 | AB14: 0 | AC14: 1 | AD14: =VLOOKUP(B14,[4]PCS!$D$1:$E$65536,2,0) -> 2066 | AE14: =VLOOKUP(B14,[4]PCS!$D$1:$F$65536,3,0) -> 334 | AF14: =VLOOKUP(B14,[4]PCS!$D$1:$G$65536,4,0) -> 0 | AG14: 1 | AH14: =VLOOKUP(C14,[5]Sheet1!$C$1:$D$65536,2,0) -> 1800 | AI14: =VLOOKUP(C14,[5]Sheet1!$C$1:$F$65536,3,0) -> 0 | AJ14: =VLOOKUP(C14,[5]Sheet1!$C$1:$F$65536,4,0) -> 0
A15: 12 | B15: DV61161 BZ101G5 | C15: G-005=PILLAR FR BODY INNER RH | D15: PRESS A | F15: 3562 | G15: 520 | H15: 16 | J15: 3572 | K15: 493 | L15: 2 | N15: 3850 | O15: 1827 | P15: 3 | R15: 1554 | S15: 593 | T15: 0 | V15: 3968 | W15: 1752 | X15: 0 | Z15: 4680 | AA15: 1508 | AB15: 0 | AC15: 1 | AD15: 5220 | AE15: 0 | AF15: =VLOOKUP(B15,[4]PCS!$D$1:$G$65536,4,0) -> 0 | AG15: 1 | AH15: =VLOOKUP(C15,[5]Sheet1!$C$1:$D$65536,2,0) -> 4104 | AI15: =VLOOKUP(C15,[5]Sheet1!$C$1:$F$65536,3,0) -> 0 | AJ15: =VLOOKUP(C15,[5]Sheet1!$C$1:$F$65536,4,0) -> 3
A16: 13 | B16: DV61162 BZ111G8 | C16: G-008=PILLAR FR BODY INNER LH | D16: PRESS A | F16: 2622 | G16: 392 | H16: 0 | J16: 2413 | K16: 800 | L16: 1 | N16: 3875 | O16: 1257 | P16: 3 | R16: 703 | S16: 740 | T16: 0 | V16: 2521 | W16: 1399 | X16: 0 | Z16: 2584 | AA16: 1745 | AB16: 0 | AC16: 1 | AD16: =VLOOKUP(B16,[4]PCS!$D$1:$E$65536,2,0) -> 3868 | AE16: =VLOOKUP(B16,[4]PCS!$D$1:$F$65536,3,0) -> 773 | AF16: =VLOOKUP(B16,[4]PCS!$D$1:$G$65536,4,0) -> 0 | AG16: 1 | AH16: =VLOOKUP(C16,[5]Sheet1!$C$1:$D$65536,2,0) -> 3518 | AI16: =VLOOKUP(C16,[5]Sheet1!$C$1:$F$65536,3,0) -> 0 | AJ16: =VLOOKUP(C16,[5]Sheet1!$C$1:$F$65536,4,0) -> 2
A17: 14 | B17: DV64136 BZ020G20 | C17: G-020=REINFORCEMENT BACK CORNER OUTER LH | D17: PRESS A | F17: 406 | G17: 26 | H17: 0 | J17: 293 | K17: 7 | L17: 0 | N17: 173 | O17: 37 | P17: 0 | R17: 223 | S17: 20 | T17: 0 | V17: 371 | W17: 49 | X17: 0 | Z17: 446 | AA17: 83 | AB17: 0 | AC17: 1 | AD17: =VLOOKUP(B17,[4]PCS!$D$1:$E$65536,2,0) -> 356 | AE17: =VLOOKUP(B17,[4]PCS!$D$1:$F$65536,3,0) -> 28 | AF17: =VLOOKUP(B17,[4]PCS!$D$1:$G$65536,4,0) -> 0 | AG17: 1 | AH17: =VLOOKUP(C17,[5]Sheet1!$C$1:$D$65536,2,0) -> 450 | AI17: =VLOOKUP(C17,[5]Sheet1!$C$1:$F$65536,3,0) -> 0 | AJ17: =VLOOKUP(C17,[5]Sheet1!$C$1:$F$65536,4,0) -> 0
A18: 15 | B18: DV58114 BZ020 | C18: G-031=PANEL, FR FLOOR, CTR RR | D18: PRESS A | F18: 2807 | G18: 259 | H18: 0 | J18: 3171 | K18: 448 | L18: 0 | N18: 3098 | O18: 552 | P18: 0 | R18: 1625 | S18: 375 | T18: 18 | V18: 2627 | W18: 931 | X18: 0 | Z18: 4525 | AA18: 1214 | AB18: 2 | AC18: 1 | AD18: 5920 | AE18: 0 | AF18: =VLOOKUP(B18,[4]PCS!$D$1:$G$65536,4,0) -> 0 | AG18: 1 | AH18: =VLOOKUP(C18,[5]Sheet1!$C$1:$D$65536,2,0) -> 5899 | AI18: =VLOOKUP(C18,[5]Sheet1!$C$1:$F$65536,3,0) -> 0 | AJ18: =VLOOKUP(C18,[5]Sheet1!$C$1:$F$65536,4,0) -> 0
A19: 16 | B19: DV58312 BZ020-00 | C19: GT-2519(K-1042)=PANEL RR FLOOR SIDE RR | D19: PRESS A | F19: 1325 | G19: 0 | H19: 0 | J19: 1000 | K19: 0 | L19: 0 | N19: 800 | O19: 0 | P19: 2 | AC19: 1 | AG19: 1
A20: 17 | B20: DV58312 BZ040-00 | C20: GT-2520(K-1043)=PANEL RR FLOOR SIDE RR | D20: PRESS A | F20: 275 | G20: 0 | H20: 0 | J20: 275 | K20: 0 | L20: 0 | N20: 225 | O20: 0 | P20: 1 | AC20: 1 | AG20: 1
A21: 18 | B21: D53711 BZ071-00 | C21: GT-5154(K-1056)=APRON FRT FENDER RH | D21: PRESS A | F21: 4220 | G21: 5 | H21: 16 | J21: 4200 | K21: 0 | L21: 3 | N21: 5060 | O21: 70 | P21: 0 | R21: 2430 | S21: 1 | T21: 0 | V21: 5368 | W21: 331 | X21: 0 | AC21: 1 | AG21: 1
A22: 19 | B22: D53711 BZ081-00 | C22: GT-5155 & K-1058=APRON FRT FENDER RH | D22: PRESS A | F22: 3 | G22: 0 | H22: 0 | J22: 3 | K22: 0 | L22: 0 | Z22: 1 | AA22: 0 | AB22: 0 | AC22: 1 | AD22: =VLOOKUP(B22,[4]PCS!$D$1:$E$65536,2,0) -> 6 | AE22: =VLOOKUP(B22,[4]PCS!$D$1:$F$65536,3,0) -> 0 | AF22: =VLOOKUP(B22,[4]PCS!$D$1:$G$65536,4,0) -> 0 | AG22: 1
A23: 20 | B23: D53712 BZ070-00 | C23: GT-5156(K-1057)=APRON FRT FENDER LH | D23: PRESS A | F23: 4100 | G23: 125 | H23: 16 | J23: 4364 | K23: 66 | L23: 3 | N23: 5244 | O23: 62 | P23: 0 | R23: 2410 | S23: 50 | T23: 0 | V23: 5862 | W23: 48 | X23: 5 | AC23: 1 | AG23: 1
A24: 21 | B24: D53712 BZ080-00 | C24: GT-5157(K-1059)=APRON FRT FENDER LH | D24: PRESS A | J24: 3 | K24: 0 | L24: 0 | Z24: 423 | AA24: 0 | AB24: 2 | AC24: 1 | AD24: 1938 | AE24: =VLOOKUP(B24,[4]PCS!$D$1:$F$65536,3,0) -> 0 | AF24: 1 | AG24: 1
A25: 22 | B25: DV53711 BZ260-00 | C25: GT-6246=APPRON FRT FENDER RH | D25: PRESS A | F25: 0 | G25: 750 | H25: 5 | J25: 0 | K25: 360 | L25: 49 | N25: 79 | O25: 450 | P25: 0 | R25: 30 | S25: 450 | T25: 0 | V25: 192 | W25: 180 | X25: 0 | Z25: 870 | AA25: 60 | AB25: 0 | AC25: 1 | AD25: =VLOOKUP(B25,[4]PCS!$D$1:$E$65536,2,0) -> 700 | AE25: =VLOOKUP(B25,[4]PCS!$D$1:$F$65536,3,0) -> 20 | AF25: =VLOOKUP(B25,[4]PCS!$D$1:$G$65536,4,0) -> 0 | AG25: 1 | AH25: =VLOOKUP(C25,[5]Sheet1!$C$1:$D$65536,2,0) -> 566 | AI25: =VLOOKUP(C25,[5]Sheet1!$C$1:$F$65536,3,0) -> 266 | AJ25: =VLOOKUP(C25,[5]Sheet1!$C$1:$F$65536,4,0) -> 0
A26: 23 | B26: DV53712 BZ250-00 | C26: GT-6247=APPRON FRT FENDER LH | D26: PRESS A | F26: 0 | G26: 780 | H26: 5 | J26: 0 | K26: 572 | L26: 11 | N26: 0 | O26: 450 | P26: 0 | R26: 0 | S26: 480 | T26: 0 | V26: 150 | W26: 150 | X26: 0 | Z26: 930 | AA26: 0 | AB26: 1 | AC26: 1 | AD26: 700 | AE26: =VLOOKUP(B26,[4]PCS!$D$1:$F$65536,3,0) -> 21 | AF26: 0 | AG26: 1 | AH26: =VLOOKUP(C26,[5]Sheet1!$C$1:$D$65536,2,0) -> 742 | AI26: =VLOOKUP(C26,[5]Sheet1!$C$1:$F$65536,3,0) -> 90 | AJ26: =VLOOKUP(C26,[5]Sheet1!$C$1:$F$65536,4,0) -> 0
A27: 24 | B27: D55711 BZ090-00 | C27: GT-6273(K-1015)=PANEL, COWL TOP, OUTER | D27: PRESS A | F27: 900 | G27: 0 | H27: 2 | J27: 500 | K27: 0 | L27: 0 | N27: 300 | O27: 0 | P27: 0 | R27: 500 | S27: 0 | T27: 0 | V27: 700 | W27: 0 | X27: 0 | Z27: 800 | AA27: 0 | AB27: 0 | AC27: 1 | AD27: =VLOOKUP(B27,[4]PCS!$D$1:$E$65536,2,0) -> 800 | AE27: =VLOOKUP(B27,[4]PCS!$D$1:$F$65536,3,0) -> 0 | AF27: =VLOOKUP(B27,[4]PCS!$D$1:$G$65536,4,0) -> 0 | AG27: 1 | AH27: =VLOOKUP(C27,[5]Sheet1!$C$1:$D$65536,2,0) -> 600 | AI27: =VLOOKUP(C27,[5]Sheet1!$C$1:$F$65536,3,0) -> 0 | AJ27: =VLOOKUP(C27,[5]Sheet1!$C$1:$F$65536,4,0) -> 0
A28: 25 | B28: ISFV 8975838684 | C28: IB-036=FRAME FLR UNDER RH | D28: PRESS A | F28: 1076 | G28: 0 | H28: 7 | J28: 720 | K28: 0 | L28: 3 | N28: 720 | O28: 0 | P28: 0 | R28: 840 | S28: 0 | T28: 4 | V28: 660 | W28: 0 | X28: 0 | Z28: 780 | AA28: 0 | AB28: 0 | AC28: 1 | AD28: =VLOOKUP(B28,[4]PCS!$D$1:$E$65536,2,0) -> 1320 | AE28: =VLOOKUP(B28,[4]PCS!$D$1:$F$65536,3,0) -> 0 | AF28: =VLOOKUP(B28,[4]PCS!$D$1:$G$65536,4,0) -> 0 | AG28: 1 | AH28: =VLOOKUP(C28,[5]Sheet1!$C$1:$D$65536,2,0) -> 904 | AI28: =VLOOKUP(C28,[5]Sheet1!$C$1:$F$65536,3,0) -> 0 | AJ28: =VLOOKUP(C28,[5]Sheet1!$C$1:$F$65536,4,0) -> 8
A29: 26 | B29: ISFV 8975838694 | C29: IB-037=FRAME FLR UNDER LH | D29: PRESS A | F29: 885 | G29: 0 | H29: 1 | J29: 720 | K29: 0 | L29: 0 | N29: 900 | O29: 0 | P29: 0 | R29: 618 | S29: 0 | T29: 0 | V29: 1032 | W29: 0 | X29: 0 | Z29: 900 | AA29: 0 | AB29: 0 | AC29: 1 | AD29: =VLOOKUP(B29,[4]PCS!$D$1:$E$65536,2,0) -> 960 | AE29: =VLOOKUP(B29,[4]PCS!$D$1:$F$65536,3,0) -> 0 | AF29: =VLOOKUP(B29,[4]PCS!$D$1:$G$65536,4,0) -> 0 | AG29: 1 | AH29: =VLOOKUP(C29,[5]Sheet1!$C$1:$D$65536,2,0) -> 978 | AI29: =VLOOKUP(C29,[5]Sheet1!$C$1:$F$65536,3,0) -> 0 | AJ29: =VLOOKUP(C29,[5]Sheet1!$C$1:$F$65536,4,0) -> 0
A30: 27 | B30: ISFV 8975839253 | C30: IB-050=FRAME FLOOR RR | D30: PRESS A | F30: 1016 | G30: 0 | H30: 0 | J30: 660 | K30: 0 | L30: 0 | N30: 840 | O30: 0 | P30: 0 | R30: 680 | S30: 0 | T30: 0 | V30: 740 | W30: 0 | X30: 0 | Z30: 900 | AA30: 0 | AB30: 0 | AC30: 1 | AD30: =VLOOKUP(B30,[4]PCS!$D$1:$E$65536,2,0) -> 1200 | AE30: =VLOOKUP(B30,[4]PCS!$D$1:$F$65536,3,0) -> 0 | AF30: =VLOOKUP(B30,[4]PCS!$D$1:$G$65536,4,0) -> 0 | AG30: 1 | AH30: =VLOOKUP(C30,[5]Sheet1!$C$1:$D$65536,2,0) -> 840 | AI30: =VLOOKUP(C30,[5]Sheet1!$C$1:$F$65536,3,0) -> 0 | AJ30: =VLOOKUP(C30,[5]Sheet1!$C$1:$F$65536,4,0) -> 0
A31: 28 | B31: IFGV-8975893064 | C31: IB-077=FRAME SUB ASM;FLOOR RR | D31: PRESS A | J31: 60 | K31: 0 | L31: 0 | N31: 60 | O31: 0 | P31: 0 | Z31: 120 | AA31: 0 | AB31: 0 | AC31: 1 | AD31: =VLOOKUP(B31,[4]PCS!$D$1:$E$65536,2,0) -> 120 | AE31: =VLOOKUP(B31,[4]PCS!$D$1:$F$65536,3,0) -> 0 | AF31: =VLOOKUP(B31,[4]PCS!$D$1:$G$65536,4,0) -> 0 | AG31: 1 | AH31: =VLOOKUP(C31,[5]Sheet1!$C$1:$D$65536,2,0) -> 60 | AI31: =VLOOKUP(C31,[5]Sheet1!$C$1:$F$65536,3,0) -> 0 | AJ31: =VLOOKUP(C31,[5]Sheet1!$C$1:$F$65536,4,0) -> 0
A32: 29 | B32: D58171 BZ130 | C32: NX-4143=REINF PARKING BRAKE BASE TO FLR | D32: PRESS A | F32: 7670 | G32: 0 | H32: 1 | J32: 5800 | K32: 0 | L32: 0 | N32: 4476 | O32: 0 | P32: 1 | R32: 5250 | S32: 0 | T32: 0 | V32: 4850 | W32: 0 | X32: 0 | Z32: 3550 | AA32: 0 | AB32: 0 | AC32: 1 | AD32: =VLOOKUP(B32,[4]PCS!$D$1:$E$65536,2,0) -> 4800 | AE32: =VLOOKUP(B32,[4]PCS!$D$1:$F$65536,3,0) -> 0 | AF32: =VLOOKUP(B32,[4]PCS!$D$1:$G$65536,4,0) -> 0 | AG32: 1 | AH32: =VLOOKUP(C32,[5]Sheet1!$C$1:$D$65536,2,0) -> 5315 | AI32: =VLOOKUP(C32,[5]Sheet1!$C$1:$F$65536,3,0) -> 0 | AJ32: =VLOOKUP(C32,[5]Sheet1!$C$1:$F$65536,4,0) -> 1
A33: 30 | B33: IFGV-8978500644 | C33: PB-017=FRAME UNDER LH | D33: PRESS A | F33: 1797 | G33: 0 | H33: 3 | J33: 1080 | K33: 0 | L33: 0 | N33: 1191 | O33: 0 | P33: 9 | R33: 810 | S33: 0 | T33: 0 | V33: 1602 | W33: 18 | X33: 0 | Z33: 1100 | AA33: 0 | AB33: 0 | AC33: 1 | AD33: =VLOOKUP(B33,[4]PCS!$D$1:$E$65536,2,0) -> 1740 | AE33: =VLOOKUP(B33,[4]PCS!$D$1:$F$65536,3,0) -> 0 | AF33: =VLOOKUP(B33,[4]PCS!$D$1:$G$65536,4,0) -> 0 | AG33: 1 | AH33: =VLOOKUP(C33,[5]Sheet1!$C$1:$D$65536,2,0) -> 1380 | AI33: =VLOOKUP(C33,[5]Sheet1!$C$1:$F$65536,3,0) -> 0 | AJ33: =VLOOKUP(C33,[5]Sheet1!$C$1:$F$65536,4,0) -> 0
A34: 31 | B34: IFGV-8978500635 | C34: PB-018=FRAME UNDER RH | D34: PRESS A | F34: 1379 | G34: 0 | H34: 1 | J34: 1018 | K34: 0 | L34: 2 | N34: 1440 | O34: 0 | P34: 0 | R34: 792 | S34: 0 | T34: 0 | V34: 1740 | W34: 0 | X34: 0 | Z34: 1475 | AA34: 0 | AB34: 0 | AC34: 1 | AD34: =VLOOKUP(B34,[4]PCS!$D$1:$E$65536,2,0) -> 1500 | AE34: =VLOOKUP(B34,[4]PCS!$D$1:$F$65536,3,0) -> 0 | AF34: =VLOOKUP(B34,[4]PCS!$D$1:$G$65536,4,0) -> 0 | AG34: 1 | AH34: =VLOOKUP(C34,[5]Sheet1!$C$1:$D$65536,2,0) -> 1380 | AI34: =VLOOKUP(C34,[5]Sheet1!$C$1:$F$65536,3,0) -> 0 | AJ34: =VLOOKUP(C34,[5]Sheet1!$C$1:$F$65536,4,0) -> 0
A35: 32 | B35: IFGV-8978500408 | C35: PB-070=MOUNTING BRKT | D35: PRESS A | F35: 3120 | G35: 0 | H35: 3 | J35: 2220 | K35: 0 | L35: 2 | N35: 2320 | O35: 0 | P35: 0 | R35: 2160 | S35: 0 | T35: 0 | V35: 2980 | W35: 0 | X35: 0 | Z35: 2515 | AA35: 0 | AB35: 0 | AC35: 1 | AD35: =VLOOKUP(B35,[4]PCS!$D$1:$E$65536,2,0) -> 3660 | AE35: =VLOOKUP(B35,[4]PCS!$D$1:$F$65536,3,0) -> 0 | AF35: =VLOOKUP(B35,[4]PCS!$D$1:$G$65536,4,0) -> 0 | AG35: 1 | AH35: =VLOOKUP(C35,[5]Sheet1!$C$1:$D$65536,2,0) -> 2400 | AI35: =VLOOKUP(C35,[5]Sheet1!$C$1:$F$65536,3,0) -> 0 | AJ35: =VLOOKUP(C35,[5]Sheet1!$C$1:$F$65536,4,0) -> 0
A36: 33 | B36: ISF-NPN2594434 | C36: PV-005BA1-BLK BODY SIDE RH | D36: PRESS A | F36: 1620 | G36: 0 | H36: 0 | J36: 900 | K36: 0 | L36: 0 | N36: 1080 | O36: 0 | P36: 0 | R36: 1006 | S36: 0 | T36: 0 | V36: 1716 | W36: 0 | X36: 0 | Z36: 1170 | AA36: 0 | AB36: 0 | AC36: 1 | AD36: =VLOOKUP(B36,[4]PCS!$D$1:$E$65536,2,0) -> 1494 | AE36: =VLOOKUP(B36,[4]PCS!$D$1:$F$65536,3,0) -> 0 | AF36: =VLOOKUP(B36,[4]PCS!$D$1:$G$65536,4,0) -> 0 | AG36: 1 | AH36: =VLOOKUP(C36,[5]Sheet1!$C$1:$D$65536,2,0) -> 1650 | AI36: =VLOOKUP(C36,[5]Sheet1!$C$1:$F$65536,3,0) -> 0 | AJ36: =VLOOKUP(C36,[5]Sheet1!$C$1:$F$65536,4,0) -> 0
A37: 34 | B37: ISF-NPN3465544 | C37: PV-006BA1-BLK BODY SIDE LH | D37: PRESS A | F37: 1500 | G37: 0 | H37: 0 | J37: 1269 | K37: 0 | L37: 0 | N37: 1061 | O37: 0 | P37: 0 | R37: 1410 | S37: 0 | T37: 0 | V37: 1380 | W37: 0 | X37: 0 | Z37: 1650 | AA37: 0 | AB37: 0 | AC37: 1 | AD37: =VLOOKUP(B37,[4]PCS!$D$1:$E$65536,2,0) -> 1766 | AE37: =VLOOKUP(B37,[4]PCS!$D$1:$F$65536,3,0) -> 0 | AF37: =VLOOKUP(B37,[4]PCS!$D$1:$G$65536,4,0) -> 0 | AG37: 1 | AH37: =VLOOKUP(C37,[5]Sheet1!$C$1:$D$65536,2,0) -> 1200 | AI37: =VLOOKUP(C37,[5]Sheet1!$C$1:$F$65536,3,0) -> 0 | AJ37: =VLOOKUP(C37,[5]Sheet1!$C$1:$F$65536,4,0) -> 0
A38: 35 | B38: ISF-NPN2594023 | C38: PVS-001B1-REINF WAIST DOOR OTR FRT RH | D38: PRESS A | F38: 1500 | G38: 0 | H38: 0 | J38: 1128 | K38: 0 | L38: 0 | N38: 1141 | O38: 0 | P38: 0 | R38: 1170 | S38: 0 | T38: 4 | V38: 1485 | W38: 0 | X38: 0 | Z38: 1591 | AA38: 0 | AB38: 0 | AC38: 1 | AD38: =VLOOKUP(B38,[4]PCS!$D$1:$E$65536,2,0) -> 1605 | AE38: =VLOOKUP(B38,[4]PCS!$D$1:$F$65536,3,0) -> 0 | AF38: =VLOOKUP(B38,[4]PCS!$D$1:$G$65536,4,0) -> 0 | AG38: 1 | AH38: =VLOOKUP(C38,[5]Sheet1!$C$1:$D$65536,2,0) -> 1500 | AI38: =VLOOKUP(C38,[5]Sheet1!$C$1:$F$65536,3,0) -> 0 | AJ38: =VLOOKUP(C38,[5]Sheet1!$C$1:$F$65536,4,0) -> 0
A39: 36 | B39: ISF-NPN2594024 | C39: PVS-002B1-REINF WAIST DOOR OTR RR RH | D39: PRESS A | F39: 1500 | G39: 0 | H39: 0 | J39: 1128 | K39: 0 | L39: 0 | N39: 1141 | O39: 0 | P39: 0 | R39: 1170 | S39: 0 | T39: 0 | V39: 1485 | W39: 0 | X39: 0 | Z39: 1591 | AA39: 0 | AB39: 0 | AC39: 1 | AD39: =VLOOKUP(B39,[4]PCS!$D$1:$E$65536,2,0) -> 1605 | AE39: =VLOOKUP(B39,[4]PCS!$D$1:$F$65536,3,0) -> 0 | AF39: =VLOOKUP(B39,[4]PCS!$D$1:$G$65536,4,0) -> 0 | AG39: 1 | AH39: =VLOOKUP(C39,[5]Sheet1!$C$1:$D$65536,2,0) -> 1500 | AI39: =VLOOKUP(C39,[5]Sheet1!$C$1:$F$65536,3,0) -> 0 | AJ39: =VLOOKUP(C39,[5]Sheet1!$C$1:$F$65536,4,0) -> 0
A40: 37 | B40: D52131 BZ170-00 | C40: S-1013=REINFORCEMENT, FR BUMPER | D40: PRESS A | F40: 5400 | G40: 0 | H40: 0 | J40: 5300 | K40: 0 | L40: 0 | N40: 5800 | O40: 0 | P40: 0 | R40: 5350 | S40: 0 | T40: 0 | V40: 7250 | W40: 0 | X40: 0 | Z40: 6400 | AA40: 0 | AB40: 0 | AC40: 1 | AD40: =VLOOKUP(B40,[4]PCS!$D$1:$E$65536,2,0) -> 7500 | AE40: =VLOOKUP(B40,[4]PCS!$D$1:$F$65536,3,0) -> 0 | AF40: =VLOOKUP(B40,[4]PCS!$D$1:$G$65536,4,0) -> 0 | AG40: 1 | AH40: =VLOOKUP(C40,[5]Sheet1!$C$1:$D$65536,2,0) -> 6200 | AI40: =VLOOKUP(C40,[5]Sheet1!$C$1:$F$65536,3,0) -> 0 | AJ40: =VLOOKUP(C40,[5]Sheet1!$C$1:$F$65536,4,0) -> 0
...

Sheet QTY B
A1: DATA DETAIL QTY STAMPING - 2024
A2: NO | B2: MAT'L NUMBER | C2: DESCRIPTION | D2: LINE | F2: JANUARI | J2: FEBRUARI | N2: MARET | R2: APRIL | V2: MEI | Z2: JUNI | AD2: JULI | AH2: AGUSTUS | AL2: SEPTEMBER | AP2: OKTOBER | AT2: NOVEMBER | AX2: DESEMBER
F3: OK | G3: REPAIR | H3: REJECT | J3: OK | K3: REPAIR | L3: REJECT | N3: OK | O3: REPAIR | P3: REJECT | R3: OK | S3: REPAIR | T3: REJECT | V3: OK | W3: REPAIR | X3: REJECT | Z3: OK | AA3: REPAIR | AB3: REJECT | AD3: OK | AE3: REPAIR | AF3: REJECT | AH3: OK | AI3: REPAIR | AJ3: REJECT | AL3: OK | AM3: REPAIR | AN3: REJECT | AP3: OK | AQ3: REPAIR | AR3: REJECT | AT3: OK | AU3: REPAIR | AV3: REJECT | AX3: OK | AY3: REPAIR | AZ3: REJECT
A5: 1 | B5: DV61621 BZ150-00 | C5: AA-3426=EXTENSION, QUARTER PANEL,LWR RH | D5: PRESS B | F5: 5550 | G5: 0 | H5: 0 | J5: 5700 | K5: 0 | L5: 0 | N5: 4500 | O5: 0 | P5: 0 | R5: 3750 | S5: 0 | T5: 0 | V5: 5570 | W5: 0 | X5: 0 | Z5: 5550 | AA5: 0 | AB5: 0 | AC5: 2 | AD5: 5257 | AE5: 0 | AF5: 0
A6: 2 | B6: DV61622 BZ150-00 | C6: AA-3427=EXTENSION, QUARTER PANEL, LWR LH | D6: PRESS B | F6: 5550 | G6: 0 | H6: 1 | J6: 5700 | K6: 0 | L6: 0 | N6: 4800 | O6: 0 | P6: 0 | R6: 3300 | S6: 0 | T6: 0 | V6: 5570 | W6: 0 | X6: 0 | Z6: 5550 | AA6: 0 | AB6: 0 | AC6: 2 | AD6: 5254 | AE6: 0 | AF6: 0
A7: 3 | B7: DV57453 BZ070 | C7: AAS-006=MEMBER FR FLOOR CROSS SIDE RH | D7: PRESS B | F7: 8700 | G7: 0 | H7: 0 | J7: 8600 | K7: 0 | L7: 0 | N7: 9200 | O7: 0 | P7: 0 | R7: 5300 | S7: 0 | T7: 0 | V7: 8700 | W7: 0 | X7: 0 | Z7: 8500 | AA7: 0 | AB7: 0 | AC7: 2 | AD7: 8000 | AE7: 0 | AF7: 0
A8: 4 | B8: DV57454 BZ060 | C8: AAS-007=MEMBER FR FLOOR CROSS SIDE LH | D8: PRESS B | F8: 8800 | G8: 0 | H8: 0 | J8: 8520 | K8: 0 | L8: 0 | N8: 9300 | O8: 0 | P8: 0 | R8: 5396 | S8: 0 | T8: 0 | V8: 8700 | W8: 0 | X8: 0 | Z8: 8500 | AA8: 0 | AB8: 0 | AC8: 2 | AD8: 7600 | AE8: 0 | AF8: 0
A9: 5 | B9: DV57468 BZ090-00 | C9: AE-0090=BRACKET, FR SEAT, RR RH | D9: PRESS B | F9: 17148 | G9: 0 | H9: 2 | J9: 14700 | K9: 0 | L9: 0 | N9: 13282 | O9: 0 | P9: 0 | R9: 10008 | S9: 0 | T9: 0 | V9: 16800 | W9: 0 | X9: 0 | Z9: 16212 | AA9: 0 | AB9: 0 | AC9: 2 | AD9: 15310 | AE9: 0 | AF9: 0
A10: 6 | B10: DV57469 BZ040-00 | C10: AE-0091=BRACKET, FR SEAT, RR LH | D10: PRESS B | F10: 15800 | G10: 0 | H10: 0 | J10: 15400 | K10: 0 | L10: 1 | N10: 14200 | O10: 0 | P10: 0 | R10: 11100 | S10: 0 | T10: 0 | V10: 16600 | W10: 0 | X10: 0 | Z10: 14332 | AA10: 0 | AB10: 0 | AC10: 2 | AD10: 16600 | AE10: 0 | AF10: 0
A11: 7 | B11: D58114 BZ070 | C11: AES-011=REINFORCEMENT, FR FLR PANEL, RH | D11: PRESS B | F11: 12247 | G11: 0 | H11: 3 | J11: 13000 | K11: 0 | L11: 0 | N11: 10300 | O11: 0 | P11: 0 | R11: 8400 | S11: 0 | T11: 0 | V11: 16900 | W11: 0 | X11: 0 | Z11: 10900 | AA11: 0 | AB11: 0 | AC11: 2 | AD11: 13000 | AE11: 0 | AF11: 0
A12: 8 | B12: DV58114 BZ070-03 | C12: AES-011V=REINFORCEMENT, FR FLR PANEL, RH | D12: PRESS B | F12: 3480 | G12: 0 | H12: 0 | J12: 2520 | K12: 0 | L12: 0 | N12: 3120 | O12: 0 | P12: 0 | R12: 2760 | S12: 0 | T12: 0 | V12: 2520 | W12: 0 | X12: 0 | Z12: 2760 | AA12: 0 | AB12: 0 | AC12: 2 | AD12: 3000 | AE12: 0 | AF12: 0
A13: 9 | B13: D61657 BZ100 | C13: AES-016=BRACKET, RR SHOCK ABSORBER, RH | D13: PRESS B | F13: 12500 | G13: 0 | H13: 6 | J13: 12600 | K13: 0 | L13: 0 | N13: 12200 | O13: 0 | P13: 0 | R13: 6600 | S13: 0 | T13: 0 | V13: 15700 | W13: 0 | X13: 0 | Z13: 11134 | AA13: 0 | AB13: 0 | AC13: 2 | AD13: 13760 | AE13: 0 | AF13: 0
A14: 10 | B14: D61658 BZ100 | C14: AES-017=BRACKET, RR SHOCK ABSORBER, LH | D14: PRESS B | F14: 11725 | G14: 0 | H14: 5 | J14: 13930 | K14: 0 | L14: 0 | N14: 10380 | O14: 0 | P14: 0 | R14: 7202 | S14: 0 | T14: 0 | V14: 14912 | W14: 0 | X14: 0 | Z14: 12190 | AA14: 0 | AB14: 0 | AC14: 2 | AD14: 13443 | AE14: 0 | AF14: 0
A15: 11 | B15: D55741 BZ560 | C15: AES-023=PANEL, COWL TOP, INNER | D15: PRESS B | F15: 4500 | G15: 0 | H15: 2 | J15: 7620 | K15: 0 | L15: 0 | N15: 5460 | O15: 0 | P15: 0 | R15: 4200 | S15: 0 | T15: 0 | V15: 6420 | W15: 0 | X15: 0 | Z15: 7380 | AA15: 0 | AB15: 0 | AC15: 2 | AD15: 5940 | AE15: 0 | AF15: 0
A16: 12 | B16: D61627 BZ110 | C16: AES-028=EXTENSION, QRTR PNL,RR LWR | D16: PRESS B | F16: 8160 | G16: 0 | H16: 3 | J16: 9780 | K16: 0 | L16: 0 | N16: 7320 | O16: 0 | P16: 5 | AC16: 2
A17: 13 | B17: D61627 BZ120 | C17: AES-029=EXTENSION, QRTR PNL,RR LWR RH | D17: PRESS B | F17: 2490 | G17: 0 | H17: 0 | J17: 2640 | K17: 0 | L17: 0 | N17: 2220 | O17: 0 | P17: 0 | AC17: 2
A18: 14 | B18: D61628 BZ160 | C18: AES-033=EXTENSION, QRTR PNL,RR LWR | D18: PRESS B | F18: 8160 | G18: 0 | H18: 0 | J18: 9780 | K18: 0 | L18: 0 | N18: 7320 | O18: 0 | P18: 5 | AC18: 2
A19: 15 | B19: D61628 BZ170 | C19: AES-034=EXTENSION, QRTR PNL,RR LWR | D19: PRESS B | F19: 2490 | G19: 0 | H19: 0 | J19: 2640 | K19: 0 | L19: 0 | N19: 2220 | O19: 0 | P19: 0 | AC19: 2
A20: 16 | B20: D61627 BZ170 | C20: AES-049=EXTENSION, QRR PNL,RR LWR RH | D20: PRESS B | F20: 1800 | G20: 0 | H20: 0 | J20: 1860 | K20: 0 | L20: 0 | N20: 1500 | O20: 0 | P20: 0 | R20: 1200 | S20: 0 | T20: 0 | V20: 1320 | W20: 0 | X20: 0 | Z20: 1680 | AA20: 0 | AB20: 0 | AC20: 2 | AD20: 1080 | AE20: 0 | AF20: 0
A21: 17 | B21: D61628 BZ220 | C21: AES-050=EXTENSION, QRR PNL,RR LWR LH | D21: PRESS B | F21: 1800 | G21: 0 | H21: 0 | J21: 1860 | K21: 0 | L21: 0 | N21: 1500 | O21: 0 | P21: 0 | R21: 1200 | S21: 0 | T21: 0 | V21: 1320 | W21: 0 | X21: 0 | Z21: 1680 | AA21: 0 | AB21: 0 | AC21: 2 | AD21: 1080 | AE21: 0 | AF21: 0
A22: 18 | B22: IFG-8976955920 | C22: AH-008GU=CROSSMEMBER 3RD | D22: PRESS B | F22: 480 | G22: 0 | H22: 0 | J22: 768 | K22: 0 | L22: 0 | N22: 830 | O22: 0 | P22: 0 | R22: 528 | S22: 0 | T22: 0 | V22: 1128 | W22: 0 | X22: 0 | Z22: 780 | AA22: 0 | AB22: 0 | AC22: 2 | AD22: 1020 | AE22: 0 | AF22: 0
A23: 19 | B23: DV61161 BZ091G3 | C23: G-003=PILLAR FR BODY INNER RH | D23: PRESS B | F23: 394 | G23: 36 | H23: 1 | J23: 222 | K23: 78 | L23: 0 | N23: 39 | O23: 81 | P23: 0 | R23: 153 | S23: 91 | T23: 0 | V23: 489 | W23: 231 | X23: 0 | Z23: 637 | AA23: 111 | AB23: 0 | AC23: 2 | AD23: 373 | AE23: 43 | AF23: 0
A24: 20 | B24: DV61161 BZ131G9 | C24: G-009=PILLAR FR BODY INNER RH | D24: PRESS B | F24: 226 | G24: 14 | H24: 0 | J24: 59 | K24: 1 | L24: 0 | N24: 212 | O24: 108 | P24: 0 | R24: 170 | S24: 23 | T24: 0 | V24: 154 | W24: 146 | X24: 0 | Z24: 94 | AA24: 26 | AB24: 0 | AC24: 2 | AD24: 378 | AE24: 42 | AF24: 0
A25: 21 | B25: DV61344 BZ070G13 | C25: G-013=PILLAR CTR BODY INNER LH | D25: PRESS B | F25: 1376 | G25: 23 | H25: 0 | J25: 960 | K25: 0 | L25: 0 | N25: 879 | O25: 21 | P25: 0 | R25: 959 | S25: 17 | T25: 0 | V25: 1898 | W25: 22 | X25: 0 | Z25: 2477 | AA25: 13 | AB25: 0 | AC25: 2 | AD25: 2872 | AE25: 8 | AF25: 0
A26: 22 | B26: DV61343 BZ080G14 | C26: G-014=PILLAR CTR BODY INNER RH | D26: PRESS B | F26: 1378 | G26: 9 | H26: 0 | J26: 960 | K26: 0 | L26: 0 | N26: 876 | O26: 24 | P26: 0 | R26: 949 | S26: 35 | T26: 0 | V26: 1884 | W26: 36 | X26: 0 | Z26: 2486 | AA26: 0 | AB26: 0 | AC26: 2 | AD26: 2805 | AE26: 75 | AF26: 0
A27: 23 | B27: DV61343 BZ090G15 | C27: G-015=PILLAR CTR BODY INNER LH | D27: PRESS B | F27: 120 | G27: 0 | H27: 0 | J27: 299 | K27: 1 | L27: 0 | N27: 240 | O27: 0 | P27: 0 | R27: 60 | S27: 0 | T27: 0 | V27: 246 | W27: 54 | X27: 0 | Z27: 240 | AA27: 0 | AB27: 0 | AC27: 2 | AD27: 300 | AE27: 0 | AF27: 0
A28: 24 | B28: DV61343 BZ090G16 | C28: G-016=PILLAR CTR BODY INNER RH | D28: PRESS B | F28: 120 | G28: 0 | H28: 0 | J28: 298 | K28: 2 | L28: 0 | N28: 240 | O28: 0 | P28: 0 | R28: 60 | S28: 0 | T28: 0 | V28: 300 | W28: 0 | X28: 0 | Z28: 240 | AA28: 0 | AB28: 0 | AC28: 2 | AD28: 290 | AE28: 10 | AF28: 0
A29: 25 | B29: DV64135 BZ010G17 | C29: G-017=REINFORCEMENT BACK CORNER OUTER RH | D29: PRESS B | F29: 3106 | G29: 134 | H29: 0 | J29: 3763 | K29: 47 | L29: 0 | N29: 4247 | O29: 203 | P29: 0 | R29: 1831 | S29: 104 | T29: 0 | V29: 4184 | W29: 116 | X29: 0 | Z29: 4144 | AA29: 252 | AB29: 0 | AC29: 2 | AD29: 4389 | AE29: 120 | AF29: 0
A30: 26 | B30: DV64136 BZ010G18 | C30: G-018=REINFORCEMENT BACK CORNER OUTER LH | D30: PRESS B | F30: 2764 | G30: 116 | H30: 0 | J30: 3775 | K30: 95 | L30: 0 | N30: 3875 | O30: 365 | P30: 0 | R30: 1632 | S30: 55 | T30: 0 | V30: 3776 | W30: 164 | X30: 0 | Z30: 3738 | AA30: 169 | AB30: 0 | AC30: 2 | AD30: 3839 | AE30: 157 | AF30: 0
A31: 27 | B31: DV64123 BZ011G21 | C31: G-021=PANEL BACK CORNER INSIDE RH | D31: PRESS B | F31: 3540 | G31: 0 | H31: 0 | J31: 3640 | K31: 20 | L31: 0 | N31: 4914 | O31: 6 | P31: 0 | R31: 1680 | S31: 4 | T31: 0 | V31: 4427 | W31: 13 | X31: 0 | Z31: 4148 | AA31: 52 | AB31: 0 | AC31: 2 | AD31: 4620 | AE31: 0 | AF31: 0
... A34: 30 | B34: DV58111 BZ410 | C34: G-034=PAN FRT FLOOR | D34: PRESS B | F34: 750 | G34: 0 | H34: 0 | J34: 350 | K34: 0 | L34: 0 | N34: 474 | O34: 0 | P34: 0 | R34: 320 | S34: 0 | T34: 0 | V34: 650 | W34: 0 | X34: 0 | Z34: 850 | AA34: 0 | AB34: 0 | AC34: 2 | AD34: 800 | AE34: 0 | AF34: 0
A35: 31 | B35: DV58114 BZ090 | C35: G-035=PNL FRT FOOR CTR REAR | D35: PRESS B | F35: 96 | G35: 4 | H35: 0 | R35: 38 | S35: 62 | T35: 0 | V35: 100 | W35: 0 | X35: 0 | Z35: 88 | AA35: 12 | AB35: 0 | AC35: 2 | AD35: 171 | AE35: 29 | AF35: 0
A36: 32 | B36: ISFV 8975895451 | C36: IB-054=BRACKET CAB MTG | D36: PRESS B | F36: 1980 | G36: 0 | H36: 0 | J36: 1380 | K36: 0 | L36: 1 | N36: 1742 | O36: 0 | P36: 1 | R36: 1560 | S36: 0 | T36: 0 | V36: 1713 | W36: 0 | X36: 0 | Z36: 1643 | AA36: 62 | AB36: 0 | AC36: 2 | AD36: 2280 | AE36: 0 | AF36: 0
A37: 33 | B37: ISF NPN6955321 | C37: IF-013=CROSSMEMBER;1ST | D37: PRESS B | F37: 0 | G37: 919 | H37: 0 | J37: 0 | K37: 462 | L37: 0 | N37: 0 | O37: 1086 | P37: 0 | R37: 0 | S37: 653 | T37: 0 | V37: 0 | W37: 1200 | X37: 0 | Z37: 0 | AA37: 766 | AB37: 0 | AC37: 2 | AD37: 0 | AE37: 720 | AF37: 0
A38: 34 | B38: ISF NPN6955331 | C38: IF-015=CROSSMEMBER 2ND ASM | D38: PRESS B | F38: 0 | G38: 840 | H38: 0 | J38: 0 | K38: 780 | L38: 0 | N38: 0 | O38: 1020 | P38: 0 | R38: 0 | S38: 936 | T38: 0 | V38: 0 | W38: 900 | X38: 0 | Z38: 0 | AA38: 826 | AB38: 0 | AC38: 2
A39: 35 | B39: VV-D61621-BZ110 | C39: NA-053=EXTENSION, QURTER PANEL, LOWER RH | D39: PRESS B | F39: 5900 | G39: 0 | H39: 2 | J39: 6796 | K39: 0 | L39: 4 | N39: 5200 | O39: 0 | P39: 0 | R39: 4000 | S39: 0 | T39: 0 | V39: 6600 | W39: 0 | X39: 0 | Z39: 5900 | AA39: 0 | AB39: 0 | AC39: 2 | AD39: 4700 | AE39: 0 | AF39: 0
A40: 36 | B40: VV-D61622-BZ140 | C40: NA-056=EXTENSION, QURTER PANEL, LOWER LH | D40: PRESS B | F40: 5900 | G40: 0 | H40: 6 | J40: 6796 | K40: 0 | L40: 4 | N40: 5200 | O40: 0 | P40: 0 | R40: 4000 | S40: 0 | T40: 0 | V40: 6600 | W40: 0 | X40: 0 | Z40: 5800 | AA40: 0 | AB40: 0 | AC40: 2 | AD40: 4800 | AE40: 0 | AF40: 0
A41: 37 | B41: DVM57258 BZ030-00 | C41: NX-2928= BRKT ENG RR MOUNTING MEMBER LH | D41: PRESS B | F41: 8900 | G41: 0 | H41: 0 | J41: 4400 | K41: 0 | L41: 0 | N41: 5000 | O41: 0 | P41: 0 | R41: 4900 | S41: 0 | T41: 0 | V41: 5435 | W41: 0 | X41: 0 | Z41: 4100 | AA41: 0 | AB41: 0 | AC41: 2 | AD41: 4000 | AE41: 0 | AF41: 0
